Workbook

Sheet LEIA-ME
A1: IRPF JOSÉ ADALMO — MEMÓRIA DE CÁLCULO PARA REGULARIZAÇÃO (BR–EUA)
A2: Contribuinte: José Adalmo Carvalho de Barros — CPF 069.351.996-70 | Cônjuge: Márcia Novais de Melo Barros — CPF 023.515.229-31
A3: Responsável técnico: Robson Soares Bezerra — CRC/PR 062711/O | Elaborado em 24/07/2026 | Data-base editável em 00_PARAMETROS!B4
A5: TRILHA DE AUDITORIA: Documento → valor extraído → câmbio → R$ → regra → imposto → crédito → juros/multa → saldo (abas 03 → 05/04 → 07 → 06 → 08 → 01).
A6: LEGENDA: células amarelas com fonte azul = entrada editável | laranja = pendência | azul-claro = totais | todas as demais são fórmulas.
A7: TAGS: [FATO CONFIRMADO] documento lido | [INFERÊNCIA TÉCNICA] conclusão a partir de norma + fato | [HIPÓTESE] premissa não comprovada | [SUGESTÃO] recomendação.
A9: REGRA CRÍTICA: nenhum valor PENDENTE vira imposto devido. Os cenários A/B medem exposição máxima; o 'Total payable' inclui só o apurado e exigível.
A11: COMO USAR
A12: 1. Em 04_BANK_TRANSACTIONS, coluna K, escolha a natureza comprovada de cada entrada de terceiros. Para GCAP, informe o ganho na coluna M.
A13: 2. Ajuste a data-base (00_PARAMETROS!B4) para a data do pagamento pretendido; os juros SELIC e a multa recalculam sozinhos.
A14: 3. Atualize a tabela SELIC com os meses seguintes (fonte BCB SGS 4390 / tabela RFB).
A15: 4. Se surgir prova de outra data de saída, altere 00_PARAMETROS!B5 — a linha do tempo é ajustada manualmente na aba 02 (colunas B/C).
... A18: Limitação: esta memória não substitui parecer jurídico-tributário individualizado. Os valores do AC 2018 são informativos (crédito extinto pela decadência).

Sheet 01_EXECUTIVE_SUMMARY
A1: 01 — RESUMO EXECUTIVO POR ANO (valores em R$)
A2: José Adalmo Carvalho de Barros — CPF 069.351.996-70 | Resp. técnico: Robson Soares Bezerra — CRC/PR 062711/O
A3: ="Data-base: "&TEXT('00_PARAMETROS'!$B$4,"DD/MM/YYYY")&" — Total payable = somente valores exigíveis e apurados. Cenários = exposição se as entradas PENDENTES forem renda de fonte BR (não é imposto devido)." -> Data-base: 30/09/2026 — Total payable = somente valores exigíveis e apurados. Cenários = exposição se as entradas PENDENTES forem renda de fonte BR (não é imposto devido).
A5: Year | B5: Tax residency | C5: Taxable income (BR) | D5: Brazilian tax | E5: U.S. tax potentially creditable | F5: Tax already paid | G5: Interest | H5: Penalties | I5: Updated balance | J5: Total payable | K5: Exposição Cenário A (atualiz.) | L5: Exposição Cenário B (atualiz.) | M5: Status
A6: 2018 | B6: ='02_TAX_TIMELINE'!B7 -> RESIDENTE | C6: ='07_BRAZIL_TAX_CALCULATION'!B22 -> 92634.55 | D6: ='07_BRAZIL_TAX_CALCULATION'!B30 -> 10434.74 | E6: ='06_FOREIGN_TAX_CREDIT'!B14 -> 0 | F6: ='07_BRAZIL_TAX_CALCULATION'!B31 -> 0 | G6: ='08_INTEREST_PENALTIES'!H6 -> 7167.62 | H6: ='08_INTEREST_PENALTIES'!I6 -> 2086.95 | I6: ='08_INTEREST_PENALTIES'!J6 -> 19689.31 | J6: ='08_INTEREST_PENALTIES'!K6 -> 0 | K6: 0 | L6: 0 | M6: ='02_TAX_TIMELINE'!G7&" — informativo" -> DECAÍDO — informativo
A7: 2019 | B7: ='02_TAX_TIMELINE'!B8 -> PARCIAL | C7: ='07_BRAZIL_TAX_CALCULATION'!E50+'07_BRAZIL_TAX_CALCULATION'!B43 -> 2569.89 | D7: ='07_BRAZIL_TAX_CALCULATION'!F50 -> 0 | E7: 0 | F7: 0 | G7: ='08_INTEREST_PENALTIES'!J8-'08_INTEREST_PENALTIES'!B8 -> 0 | H7: 0 | I7: ='08_INTEREST_PENALTIES'!J8 -> 0 | J7: ='08_INTEREST_PENALTIES'!K8 -> 0 | K7: ='08_INTEREST_PENALTIES'!J9 -> 0 | L7: ='08_INTEREST_PENALTIES'!J10 -> 0 | M7: ='02_TAX_TIMELINE'!G8&IF('07_BRAZIL_TAX_CALCULATION'!D50>0," — PENDENTE — DOCUMENTO NECESSÁRIO","") -> DECAÍDO
A8: 2020 | B8: ='02_TAX_TIMELINE'!B9 -> NÃO RESIDENTE | C8: ='07_BRAZIL_TAX_CALCULATION'!E51 -> 0 | D8: ='07_BRAZIL_TAX_CALCULATION'!F51 -> 0 | E8: 0 | F8: 0 | G8: ='08_INTEREST_PENALTIES'!J11-'08_INTEREST_PENALTIES'!B11 -> 0 | H8: 0 | I8: ='08_INTEREST_PENALTIES'!J11 -> 0 | J8: ='08_INTEREST_PENALTIES'!K11 -> 0 | K8: ='08_INTEREST_PENALTIES'!J12 -> 0 | L8: ='08_INTEREST_PENALTIES'!J13 -> 0 | M8: ='02_TAX_TIMELINE'!G9&IF('07_BRAZIL_TAX_CALCULATION'!D51>0," — PENDENTE — DOCUMENTO NECESSÁRIO","") -> DECAÍDO
A9: 2021 | B9: ='02_TAX_TIMELINE'!B10 -> NÃO RESIDENTE | C9: ='07_BRAZIL_TAX_CALCULATION'!E52 -> 0 | D9: ='07_BRAZIL_TAX_CALCULATION'!F52 -> 0 | E9: 0 | F9: 0 | G9: ='08_INTEREST_PENALTIES'!J14-'08_INTEREST_PENALTIES'!B14 -> 0 | H9: 0 | I9: ='08_INTEREST_PENALTIES'!J14 -> 0 | J9: ='08_INTEREST_PENALTIES'!K14 -> 0 | K9: ='08_INTEREST_PENALTIES'!J15 -> 0 | L9: ='08_INTEREST_PENALTIES'!J16 -> 0 | M9: ='02_TAX_TIMELINE'!G10&IF('07_BRAZIL_TAX_CALCULATION'!D52>0," — PENDENTE — DOCUMENTO NECESSÁRIO","") -> ABERTO
A10: 2022 | B10: ='02_TAX_TIMELINE'!B11 -> NÃO RESIDENTE | C10: ='07_BRAZIL_TAX_CALCULATION'!E53 -> 0 | D10: ='07_BRAZIL_TAX_CALCULATION'!F53 -> 0 | E10: 0 | F10: 0 | G10: ='08_INTEREST_PENALTIES'!J17-'08_INTEREST_PENALTIES'!B17 -> 0 | H10: 0 | I10: ='08_INTEREST_PENALTIES'!J17 -> 0 | J10: ='08_INTEREST_PENALTIES'!K17 -> 0 | K10: ='08_INTEREST_PENALTIES'!J18 -> 0 | L10: ='08_INTEREST_PENALTIES'!J19 -> 0 | M10: ='02_TAX_TIMELINE'!G11&IF('07_BRAZIL_TAX_CALCULATION'!D53>0," — PENDENTE — DOCUMENTO NECESSÁRIO","") -> ABERTO
A11: 2023 | B11: ='02_TAX_TIMELINE'!B12 -> NÃO RESIDENTE | C11: ='07_BRAZIL_TAX_CALCULATION'!E54 -> 0 | D11: ='07_BRAZIL_TAX_CALCULATION'!F54 -> 0 | E11: 0 | F11: 0 | G11: ='08_INTEREST_PENALTIES'!J20-'08_INTEREST_PENALTIES'!B20 -> 0 | H11: 0 | I11: ='08_INTEREST_PENALTIES'!J20 -> 0 | J11: ='08_INTEREST_PENALTIES'!K20 -> 0 | K11: ='08_INTEREST_PENALTIES'!J21 -> 0 | L11: ='08_INTEREST_PENALTIES'!J22 -> 0 | M11: ='02_TAX_TIMELINE'!G12&IF('07_BRAZIL_TAX_CALCULATION'!D54>0," — PENDENTE — DOCUMENTO NECESSÁRIO","") -> ABERTO
A12: 2024 | B12: ='02_TAX_TIMELINE'!B13 -> NÃO RESIDENTE | C12: ='07_BRAZIL_TAX_CALCULATION'!E55 -> 0 | D12: ='07_BRAZIL_TAX_CALCULATION'!F55 -> 0 | E12: 0 | F12: 0 | G12: ='08_INTEREST_PENALTIES'!J23-'08_INTEREST_PENALTIES'!B23 -> 0 | H12: 0 | I12: ='08_INTEREST_PENALTIES'!J23 -> 0 | J12: ='08_INTEREST_PENALTIES'!K23 -> 0 | K12: ='08_INTEREST_PENALTIES'!J24 -> 10275.31 | L12: ='08_INTEREST_PENALTIES'!J25 -> 17125.53 | M12: ='02_TAX_TIMELINE'!G13&IF('07_BRAZIL_TAX_CALCULATION'!D55>0," — PENDENTE — DOCUMENTO NECESSÁRIO","") -> ABERTO — PENDENTE — DOCUMENTO NECESSÁRIO
A13: 2025 | B13: ='02_TAX_TIMELINE'!B14 -> NÃO RESIDENTE | C13: ='07_BRAZIL_TAX_CALCULATION'!E56 -> 0 | D13: ='07_BRAZIL_TAX_CALCULATION'!F56 -> 0 | E13: 0 | F13: 0 | G13: ='08_INTEREST_PENALTIES'!J26-'08_INTEREST_PENALTIES'!B26 -> 0 | H13: 0 | I13: ='08_INTEREST_PENALTIES'!J26 -> 0 | J13: ='08_INTEREST_PENALTIES'!K26 -> 0 | K13: ='08_INTEREST_PENALTIES'!J27 -> 117339.42 | L13: ='08_INTEREST_PENALTIES'!J28 -> 195565.68 | M13: ='02_TAX_TIMELINE'!G14&IF('07_BRAZIL_TAX_CALCULATION'!D56>0," — PENDENTE — DOCUMENTO NECESSÁRIO","") -> ABERTO — PENDENTE — DOCUMENTO NECESSÁRIO
A14: 2026 | B14: ='02_TAX_TIMELINE'!B15 -> NÃO RESIDENTE | C14: ='07_BRAZIL_TAX_CALCULATION'!E57 -> 0 | D14: ='07_BRAZIL_TAX_CALCULATION'!F57 -> 0 | E14: 0 | F14: 0 | G14: ='08_INTEREST_PENALTIES'!J29-'08_INTEREST_PENALTIES'!B29 -> 0 | H14: 0 | I14: ='08_INTEREST_PENALTIES'!J29 -> 0 | J14: ='08_INTEREST_PENALTIES'!K29 -> 0 | K14: ='08_INTEREST_PENALTIES'!J30 -> 1506 | L14: ='08_INTEREST_PENALTIES'!J31 -> 2510 | M14: ='02_TAX_TIMELINE'!G15&IF('07_BRAZIL_TAX_CALCULATION'!D57>0," — PENDENTE — DOCUMENTO NECESSÁRIO","") -> ABERTO — PENDENTE — DOCUMENTO NECESSÁRIO
A15: TOTAL | C15: =SUM(C6:C14) -> 95204.44 | D15: =SUM(D6:D14) -> 10434.74 | E15: =SUM(E6:E14) -> 0 | F15: =SUM(F6:F14) -> 0 | G15: =SUM(G6:G14) -> 7167.62 | H15: =SUM(H6:H14) -> 2086.95 | I15: =SUM(I6:I14) -> 19689.31 | J15: =SUM(J6:J14) -> 0 | ... L15: =SUM(L6:L14) -> 215201.21
A17: Nota: nos anos de não residência, a coluna Interest mostra juros + multa de mora agregados (cálculo linha a linha na aba 04).
A19: INDICADORES-CHAVE
A20: Recebimentos de terceiros no BR sem natureza comprovada (R$) | E20: ='04_BANK_TRANSACTIONS'!F171 -> 623510
A21: Qtde. de recebimentos materiais pendentes | E21: ='04_BANK_TRANSACTIONS'!F172 -> 15
A22: Imóveis 2025 — preço contratado (R$) | E22: ='09_REAL_ESTATE'!D7 -> 1620265
A23: Imóveis — vencido em 2025 sem pagamento rastreado no Nubank (R$) | E23: ='09_REAL_ESTATE'!D12 -> 219215
A24: Pendências críticas em aberto | E24: =COUNTIFS('11_RISKS'!D:D,"ALTO",'11_RISKS'!H:H,"ABERTO")+COUNTIFS('11_RISKS'!D:D,"CRÍTICO",'11_RISKS'!H:H,"ABERTO") -> 5

Sheet 02_TAX_TIMELINE
A1: 02 — LINHA DO TEMPO DE RESIDÊNCIA E OBRIGAÇÕES (2016–2026)
A2: José Adalmo Carvalho de Barros — CPF 069.351.996-70 | Resp. técnico: Robson Soares Bezerra — CRC/PR 062711/O
A3: Decadência: sem declaração e sem pagamento → CTN art. 173, I (1º dia do exercício seguinte àquele em que o lançamento poderia ser efetuado + 5 anos) — STJ, Súmula 555 [INFERÊNCIA TÉCNICA]. Para AC 2020+ refere-se ao IRRF de fonte BR (fato gerador no próprio ano).
A4: AC | B4: Situação fiscal | C4: Período | D4: Obrigação declaratória | E4: Prazo de entrega | F4: Decadência (CTN 173, I) | G4: Status na data-base | H4: Tributo BR sobre renda EUA? | I4: Risco | J4: Nota técnica
A5: 2016 | B5: RESIDENTE | C5: 01/01–31/12/2016 | D5: DIRPF — ENTREGUE (recibo na pasta) | E5: 42853 | F5: =DATE(A5+6,12,31) -> 44926 | G5: =IF('00_PARAMETROS'!$B$4>F5,"DECAÍDO","ABERTO") -> DECAÍDO | H5: Não | I5: BAIXO | J5: [FATO CONFIRMADO] DEC + REC na pasta 2017/.
A6: 2017 | B6: RESIDENTE | C6: 01/01–31/12/2017 | D6: DIRPF — entrega informada, sem recibo | E6: 43220 | F6: =DATE(A6+6,12,31) -> 45291 | G6: =IF('00_PARAMETROS'!$B$4>F6,"DECAÍDO","ABERTO") -> DECAÍDO | H6: Não | I6: BAIXO | J6: [HIPÓTESE] Cliente afirma entrega; recibo não localizado. Decaído.
A7: 2018 | B7: RESIDENTE | C7: 01/01–31/12/2018 (ausente desde 25/01, sem CSDP) | D7: DIRPF obrigatória — NÃO ENTREGUE | E7: 43585 | F7: =DATE(A7+6,12,31) -> 45657 | G7: =IF('00_PARAMETROS'!$B$4>F7,"DECAÍDO","ABERTO") -> DECAÍDO | H7: SIM (rend. mundiais) | I7: MÉDIO | J7: [INFERÊNCIA TÉCNICA] W-2 US$ 25.628 > limite. Cálculo em 07 (informativo). Decaído pelo art. 173, I.
A8: 2019 | B8: PARCIAL | C8: Residente 01/01–24/01; não residente a partir de 25/01/2019 | D8: DSDP AC 2019 — NÃO ENTREGUE [INFERÊNCIA — confirmar obrigatoriedade] | E8: 44012 | F8: =DATE(YEAR(E8)+5,12,31) -> 46022 | G8: =IF('00_PARAMETROS'!$B$4>F8,"DECAÍDO","ABERTO") -> DECAÍDO | H8: Só no período residente | I8: BAIXO | J8: Prazo prorrogado para 30/06/2020 (IN RFB 1.930/2020 — confirmar). Renda do período residente < limite; sem imposto. MAED decaído.
A9: 2020 | B9: NÃO RESIDENTE | C9: Ano inteiro | D9: Sem DIRPF | F9: =DATE(A9+5,12,31) -> 46022 | G9: =IF('00_PARAMETROS'!$B$4>F9,"DECAÍDO","ABERTO") -> DECAÍDO | H9: NÃO | I9: BAIXO | J9: Renda EUA fora do alcance. Só IRRF sobre eventual renda de fonte BR.
A10: 2021 | B10: NÃO RESIDENTE | C10: Ano inteiro | D10: Sem DIRPF | F10: =DATE(A10+5,12,31) -> 46387 | G10: =IF('00_PARAMETROS'!$B$4>F10,"DECAÍDO","ABERTO") -> ABERTO | H10: NÃO | I10: BAIXO | J10: Idem. Sem extratos BR do período — PENDENTE.
A11: 2022 | B11: NÃO RESIDENTE | C11: Ano inteiro | D11: Sem DIRPF | F11: =DATE(A11+5,12,31) -> 46752 | G11: =IF('00_PARAMETROS'!$B$4>F11,"DECAÍDO","ABERTO") -> ABERTO | H11: NÃO | I11: BAIXO | J11: Idem. Extrato Nubank mai/2022 (03.pdf) referenciado; demais meses PENDENTES.
A12: 2023 | B12: NÃO RESIDENTE | C12: Ano inteiro | D12: Sem DIRPF | F12: =DATE(A12+5,12,31) -> 47118 | G12: =IF('00_PARAMETROS'!$B$4>F12,"DECAÍDO","ABERTO") -> ABERTO | H12: NÃO | I12: MÉDIO | J12: Form 1040/2023: digital assets = YES → origem/exchange PENDENTE.
A13: 2024 | B13: NÃO RESIDENTE | C13: Ano inteiro | D13: Sem DIRPF | F13: =DATE(A13+5,12,31) -> 47483 | G13: =IF('00_PARAMETROS'!$B$4>F13,"DECAÍDO","ABERTO") -> ABERTO | H13: NÃO | I13: ALTO | J13: Recebimentos de terceiros no BR (out–dez/2024) com natureza PENDENTE — ver 04.
A14: 2025 | B14: NÃO RESIDENTE | C14: Ano inteiro | D14: Sem DIRPF — NÃO transmitir o .DEC 2026 (endereço SP) | F14: =DATE(A14+5,12,31) -> 47848 | G14: =IF('00_PARAMETROS'!$B$4>F14,"DECAÍDO","ABERTO") -> ABERTO | H14: NÃO | I14: ALTO | J14: Terceiros BR R$ 574 mil + imóveis R$ 1,62 mi. Contrato Blue Ocean declara domicílio em Goioerê/PR (contradição).
A15: 2026 | B15: NÃO RESIDENTE | C15: Até a data-base | D15: Sem DIRPF | F15: =DATE(A15+5,12,31) -> 48213 | G15: =IF('00_PARAMETROS'!$B$4>F15,"DECAÍDO","ABERTO") -> ABERTO | H15: NÃO | I15: MÉDIO | J15: Reforços anuais N1 a partir de 25/07/2026 (R$ 88.850/ano) — origem dos recursos.

Sheet 03_INCOME
A1: 03 — RENDIMENTOS EXTRAÍDOS DOS DOCUMENTOS (Documento → Data → Contribuinte → Rendimento → Moeda → R$ → Tratamento → Fonte)
A2: José Adalmo Carvalho de Barros — CPF 069.351.996-70 | Resp. técnico: Robson Soares Bezerra — CRC/PR 062711/O
A4: Documento | B4: Período | C4: Contribuinte | D4: Rendimento / transação | E4: Moeda | F4: Valor original | G4: Câmbio | H4: Valor R$ | I4: Situação fiscal no período | J4: Tratamento tributário BR | K4: Status
A5: Form 1040/2018 | B5: 2018 | C5: José (MFJ c/ Márcia) | D5: W-2 wages (empregado) | E5: USD | F5: ='05_US_TAXES'!D5 -> 25628 | G5: ver 07 | H5: ='07_BRAZIL_TAX_CALCULATION'!E17 -> 92634.55 | I5: ='02_TAX_TIMELINE'!B7 -> RESIDENTE | J5: Tributável (residente) — carnê-leão + ajuste; DECAÍDO | K5: [FATO CONFIRMADO — OCR]
A6: Form 1040/2019 | B6: 2019 | C6: José | D6: Schedule C (autônomo) | E6: USD | F6: ='05_US_TAXES'!D6 -> 10000 | G6: ver 07 | H6: ='07_BRAZIL_TAX_CALCULATION'!B43 -> 2569.89 | I6: ='02_TAX_TIMELINE'!B8 -> PARCIAL | J6: Tributável só a fração 01–24/01 (abaixo do limite); restante fora do alcance | K6: [FATO CONFIRMADO — OCR]
A7: Form 1040/2020 | B7: 2020 | C7: José (MFJ c/ Márcia) | D7: Schedule C (autônomo) | E7: USD | F7: ='05_US_TAXES'!D7 -> 30152 | G7: N/A | I7: ='02_TAX_TIMELINE'!B9 -> NÃO RESIDENTE | J7: Fonte EUA, contribuinte não residente → não tributável no BR [INFERÊNCIA TÉCNICA] | K7: [FATO CONFIRMADO — OCR]
A8: Form 1040/2021 | B8: 2021 | C8: José (MFJ c/ Márcia) | D8: Schedule C (autônomo) | E8: USD | F8: ='05_US_TAXES'!D8 -> 35335 | G8: N/A | I8: ='02_TAX_TIMELINE'!B10 -> NÃO RESIDENTE | J8: Fonte EUA, contribuinte não residente → não tributável no BR [INFERÊNCIA TÉCNICA] | K8: [FATO CONFIRMADO — Fase 2]
A9: Form 1040/2022 | B9: 2022 | C9: José (MFJ c/ Márcia) | D9: Schedule C (autônomo) | E9: USD | F9: ='05_US_TAXES'!D9 -> 40550 | G9: N/A | I9: ='02_TAX_TIMELINE'!B11 -> NÃO RESIDENTE | J9: Fonte EUA, contribuinte não residente → não tributável no BR [INFERÊNCIA TÉCNICA] | K9: [FATO CONFIRMADO — OCR] (laudo F6 dizia 'a confirmar')
A10: Form 1040/2023 | B10: 2023 | C10: José (MFJ c/ Márcia) | D10: K-1 Two Brothers Drywall & Paint (EIN 37-2048597) | E10: USD | F10: ='05_US_TAXES'!D10 -> 75383 | G10: N/A | I10: ='02_TAX_TIMELINE'!B12 -> NÃO RESIDENTE | J10: Fonte EUA, contribuinte não residente → não tributável no BR [INFERÊNCIA TÉCNICA] | K10: [INFERÊNCIA TÉCNICA]
A11: Form 1040/2024 | B11: 2024 | C11: José (MFJ c/ Márcia) | D11: Sch C (DeSouza Painting 1099: 10.670) + K-1 Two Brothers, UPE, Royal Flush Inv. & Constr. (EIN 92-3349147) | E11: USD | F11: ='05_US_TAXES'!D11 -> 82153 | G11: N/A | I11: ='02_TAX_TIMELINE'!B13 -> NÃO RESIDENTE | J11: Fonte EUA, contribuinte não residente → não tributável no BR [INFERÊNCIA TÉCNICA] | K11: [FATO CONFIRMADO — PDF]; pagamento ao IRS NÃO comprovado
A12: Form 1040/2025 | B12: 2025 | C12: José | D12: Rendimentos EUA 2025 | E12: USD | G12: N/A | I12: NÃO RESIDENTE | J12: Não tributável no BR | K12: PENDENTE — DOCUMENTO NECESSÁRIO
A14: RECEBIMENTOS DE FONTE BR — ENTRADAS DE TERCEIROS (Nubank), por contraparte e ano — natureza a comprovar
A15: Documento | B15: Ano | C15: Contribuinte | D15: Contraparte | E15: Moeda | F15: Valor original | G15: Câmbio | H15: Valor R$ | I15: Situação fiscal no período | J15: Tratamento tributário BR | K15: Status
A16: Extratos Nubank | B16: 2024 | C16: José | D16: FELIPE DE MELO RODRIGUES | E16: BRL | F16: =SUMIFS('04_BANK_TRANSACTIONS'!$F$5:$F$168,'04_BANK_TRANSACTIONS'!$C$5:$C$168,2024,'04_BANK_TRANSACTIONS'!$E$5:$E$168,D16,'04_BANK_TRANSACTIONS'!$G$5:$G$168,"entrada",'04_BANK_TRANSACTIONS'!$H$5:$H$168,"terceiros") -> 44950 | G16: 1 | H16: =F16*G16 -> 44950 | I16: NÃO RESIDENTE | J16: =IF(COUNTIFS('04_BANK_TRANSACTIONS'!$C$5:$C$168,2024,'04_BANK_TRANSACTIONS'!$E$5:$E$168,D16,'04_BANK_TRANSACTIONS'!$K$5:$K$168,"PENDENTE")>0,"Natureza PENDENTE — se renda de fonte BR: IRRF 15%/25%; se empréstimo/venda de bem/doação: tratamento próprio","Classificado na aba 04") -> Natureza PENDENTE — se renda de fonte BR: IRRF 15%/25%; se empréstimo/venda de bem/doação: tratamento próprio | K16: PENDENTE — DOCUMENTO NECESSÁRIO
A17: Extratos Nubank | B17: 2024 | C17: José | D17: LEONARDO CARVALHO BARROS | E17: BRL | F17: =SUMIFS('04_BANK_TRANSACTIONS'!$F$5:$F$168,'04_BANK_TRANSACTIONS'!$C$5:$C$168,2024,'04_BANK_TRANSACTIONS'!$E$5:$E$168,D17,'04_BANK_TRANSACTIONS'!$G$5:$G$168,"entrada",'04_BANK_TRANSACTIONS'!$H$5:$H$168,"terceiros") -> 1500 | G17: 1 | H17: =F17*G17 -> 1500 | I17: NÃO RESIDENTE | J17: =IF(COUNTIFS('04_BANK_TRANSACTIONS'!$C$5:$C$168,2024,'04_BANK_TRANSACTIONS'!$E$5:$E$168,D17,'04_BANK_TRANSACTIONS'!$K$5:$K$168,"PENDENTE")>0,"Natureza PENDENTE — se renda de fonte BR: IRRF 15%/25%; se empréstimo/venda de bem/doação: tratamento próprio","Classificado na aba 04") -> Natureza PENDENTE — se renda de fonte BR: IRRF 15%/25%; se empréstimo/venda de bem/doação: tratamento próprio | K17: PENDENTE — DOCUMENTO NECESSÁRIO
A18: Extratos Nubank | B18: 2024 | C18: José | D18: DIEGO NOVAIS DE MELO FONSECA | E18: BRL | F18: =SUMIFS('04_BANK_TRANSACTIONS'!$F$5:$F$168,'04_BANK_TRANSACTIONS'!$C$5:$C$168,2024,'04_BANK_TRANSACTIONS'!$E$5:$E$168,D18,'04_BANK_TRANSACTIONS'!$G$5:$G$168,"entrada",'04_BANK_TRANSACTIONS'!$H$5:$H$168,"terceiros") -> 1000 | G18: 1 | H18: =F18*G18 -> 1000 | I18: NÃO RESIDENTE | J18: =IF(COUNTIFS('04_BANK_TRANSACTIONS'!$C$5:$C$168,2024,'04_BANK_TRANSACTIONS'!$E$5:$E$168,D18,'04_BANK_TRANSACTIONS'!$K$5:$K$168,"PENDENTE")>0,"Natureza PENDENTE — se renda de fonte BR: IRRF 15%/25%; se empréstimo/venda de bem/doação: tratamento próprio","Classificado na aba 04") -> Natureza PENDENTE — se renda de fonte BR: IRRF 15%/25%; se empréstimo/venda de bem/doação: tratamento próprio | K18: PENDENTE — DOCUMENTO NECESSÁRIO
A19: Extratos Nubank | B19: 2025 | C19: José | D19: REGINALDO FRANCISCO BESSA | E19: BRL | F19: =SUMIFS('04_BANK_TRANSACTIONS'!$F$5:$F$168,'04_BANK_TRANSACTIONS'!$C$5:$C$168,2025,'04_BANK_TRANSACTIONS'!$E$5:$E$168,D19,'04_BANK_TRANSACTIONS'!$G$5:$G$168,"entrada",'04_BANK_TRANSACTIONS'!$H$5:$H$168,"terceiros") -> 190000 | G19: 1 | H19: =F19*G19 -> 190000 | I19: NÃO RESIDENTE | J19: =IF(COUNTIFS('04_BANK_TRANSACTIONS'!$C$5:$C$168,2025,'04_BANK_TRANSACTIONS'!$E$5:$E$168,D19,'04_BANK_TRANSACTIONS'!$K$5:$K$168,"PENDENTE")>0,"Natureza PENDENTE — se renda de fonte BR: IRRF 15%/25%; se empréstimo/venda de bem/doação: tratamento próprio","Classificado na aba 04") -> Natureza PENDENTE — se renda de fonte BR: IRRF 15%/25%; se empréstimo/venda de bem/doação: tratamento próprio | K19: PENDENTE — DOCUMENTO NECESSÁRIO
A20: Extratos Nubank | B20: 2025 | C20: José | D20: ANDRE WERNER | E20: BRL | F20: =SUMIFS('04_BANK_TRANSACTIONS'!$F$5:$F$168,'04_BANK_TRANSACTIONS'!$C$5:$C$168,2025,'04_BANK_TRANSACTIONS'!$E$5:$E$168,D20,'04_BANK_TRANSACTIONS'!$G$5:$G$168,"entrada",'04_BANK_TRANSACTIONS'!$H$5:$H$168,"terceiros") -> 96000 | G20: 1 | H20: =F20*G20 -> 96000 | I20: NÃO RESIDENTE | J20: =IF(COUNTIFS('04_BANK_TRANSACTIONS'!$C$5:$C$168,2025,'04_BANK_TRANSACTIONS'!$E$5:$E$168,D20,'04_BANK_TRANSACTIONS'!$K$5:$K$168,"PENDENTE")>0,"Natureza PENDENTE — se renda de fonte BR: IRRF 15%/25%; se empréstimo/venda de bem/doação: tratamento próprio","Classificado na aba 04") -> Natureza PENDENTE — se renda de fonte BR: IRRF 15%/25%; se empréstimo/venda de bem/doação: tratamento próprio | K20: PENDENTE — DOCUMENTO NECESSÁRIO
A21: Extratos Nubank | B21: 2025 | C21: José | D21: WERSAN COMERCIO DE COMBUSTIVEIS LTDA | E21: BRL | F21: =SUMIFS('04_BANK_TRANSACTIONS'!$F$5:$F$168,'04_BANK_TRANSACTIONS'!$C$5:$C$168,2025,'04_BANK_TRANSACTIONS'!$E$5:$E$168,D21,'04_BANK_TRANSACTIONS'!$G$5:$G$168,"entrada",'04_BANK_TRANSACTIONS'!$H$5:$H$168,"terceiros") -> 69000 | G21: 1 | H21: =F21*G21 -> 69000 | I21: NÃO RESIDENTE | J21: =IF(COUNTIFS('04_BANK_TRANSACTIONS'!$C$5:$C$168,2025,'04_BANK_TRANSACTIONS'!$E$5:$E$168,D21,'04_BANK_TRANSACTIONS'!$K$5:$K$168,"PENDENTE")>0,"Natureza PENDENTE — se renda de fonte BR: IRRF 15%/25%; se empréstimo/venda de bem/doação: tratamento próprio","Classificado na aba 04") -> Natureza PENDENTE — se renda de fonte BR: IRRF 15%/25%; se empréstimo/venda de bem/doação: tratamento próprio | K21: PENDENTE — DOCUMENTO NECESSÁRIO
A22: Extratos Nubank | B22: 2025 | C22: José | D22: FELIPE DE MELO RODRIGUES | E22: BRL | F22: =SUMIFS('04_BANK_TRANSACTIONS'!$F$5:$F$168,'04_BANK_TRANSACTIONS'!$C$5:$C$168,2025,'04_BANK_TRANSACTIONS'!$E$5:$E$168,D22,'04_BANK_TRANSACTIONS'!$G$5:$G$168,"entrada",'04_BANK_TRANSACTIONS'!$H$5:$H$168,"terceiros") -> 61410 | G22: 1 | H22: =F22*G22 -> 61410 | I22: NÃO RESIDENTE | J22: =IF(COUNTIFS('04_BANK_TRANSACTIONS'!$C$5:$C$168,2025,'04_BANK_TRANSACTIONS'!$E$5:$E$168,D22,'04_BANK_TRANSACTIONS'!$K$5:$K$168,"PENDENTE")>0,"Natureza PENDENTE — se renda de fonte BR: IRRF 15%/25%; se empréstimo/venda de bem/doação: tratamento próprio","Classificado na aba 04") -> Natureza PENDENTE — se renda de fonte BR: IRRF 15%/25%; se empréstimo/venda de bem/doação: tratamento próprio | K22: PENDENTE — DOCUMENTO NECESSÁRIO
A23: Extratos Nubank | B23: 2025 | C23: José | D23: RODRIGO DE OLIVEIRA MACHADO | E23: BRL | F23: =SUMIFS('04_BANK_TRANSACTIONS'!$F$5:$F$168,'04_BANK_TRANSACTIONS'!$C$5:$C$168,2025,'04_BANK_TRANSACTIONS'!$E$5:$E$168,D23,'04_BANK_TRANSACTIONS'!$G$5:$G$168,"entrada",'04_BANK_TRANSACTIONS'!$H$5:$H$168,"terceiros") -> 44000 | G23: 1 | H23: =F23*G23 -> 44000 | I23: NÃO RESIDENTE | J23: =IF(COUNTIFS('04_BANK_TRANSACTIONS'!$C$5:$C$168,2025,'04_BANK_TRANSACTIONS'!$E$5:$E$168,D23,'04_BANK_TRANSACTIONS'!$K$5:$K$168,"PENDENTE")>0,"Natureza PENDENTE — se renda de fonte BR: IRRF 15%/25%; se empréstimo/venda de bem/doação: tratamento próprio","Classificado na aba 04") -> Natureza PENDENTE — se renda de fonte BR: IRRF 15%/25%; se empréstimo/venda de bem/doação: tratamento próprio | K23: PENDENTE — DOCUMENTO NECESSÁRIO
A24: Extratos Nubank | B24: 2025 | C24: José | D24: GEUCIR PEREIRA CALDEIRA | E24: BRL | F24: =SUMIFS('04_BANK_TRANSACTIONS'!$F$5:$F$168,'04_BANK_TRANSACTIONS'!$C$5:$C$168,2025,'04_BANK_TRANSACTIONS'!$E$5:$E$168,D24,'04_BANK_TRANSACTIONS'!$G$5:$G$168,"entrada",'04_BANK_TRANSACTIONS'!$H$5:$H$168,"terceiros") -> 40000 | G24: 1 | H24: =F24*G24 -> 40000 | I24: NÃO RESIDENTE | J24: =IF(COUNTIFS('04_BANK_TRANSACTIONS'!$C$5:$C$168,2025,'04_BANK_TRANSACTIONS'!$E$5:$E$168,D24,'04_BANK_TRANSACTIONS'!$K$5:$K$168,"PENDENTE")>0,"Natureza PENDENTE — se renda de fonte BR: IRRF 15%/25%; se empréstimo/venda de bem/doação: tratamento próprio","Classificado na aba 04") -> Natureza PENDENTE — se renda de fonte BR: IRRF 15%/25%; se empréstimo/venda de bem/doação: tratamento próprio | K24: PENDENTE — DOCUMENTO NECESSÁRIO
A25: Extratos Nubank | B25: 2025 | C25: José | D25: SUELY ANDREIA LEANDRO DO NASCIMENTO | E25: BRL | F25: =SUMIFS('04_BANK_TRANSACTIONS'!$F$5:$F$168,'04_BANK_TRANSACTIONS'!$C$5:$C$168,2025,'04_BANK_TRANSACTIONS'!$E$5:$E$168,D25,'04_BANK_TRANSACTIONS'!$G$5:$G$168,"entrada",'04_BANK_TRANSACTIONS'!$H$5:$H$168,"terceiros") -> 40000 | G25: 1 | H25: =F25*G25 -> 40000 | I25: NÃO RESIDENTE | J25: =IF(COUNTIFS('04_BANK_TRANSACTIONS'!$C$5:$C$168,2025,'04_BANK_TRANSACTIONS'!$E$5:$E$168,D25,'04_BANK_TRANSACTIONS'!$K$5:$K$168,"PENDENTE")>0,"Natureza PENDENTE — se renda de fonte BR: IRRF 15%/25%; se empréstimo/venda de bem/doação: tratamento próprio","Classificado na aba 04") -> Natureza PENDENTE — se renda de fonte BR: IRRF 15%/25%; se empréstimo/venda de bem/doação: tratamento próprio | K25: PENDENTE — DOCUMENTO NECESSÁRIO
A26: Extratos Nubank | B26: 2025 | C26: José | D26: DIEGO NOVAIS DE MELO FONSECA | E26: BRL | F26: =SUMIFS('04_BANK_TRANSACTIONS'!$F$5:$F$168,'04_BANK_TRANSACTIONS'!$C$5:$C$168,2025,'04_BANK_TRANSACTIONS'!$E$5:$E$168,D26,'04_BANK_TRANSACTIONS'!$G$5:$G$168,"entrada",'04_BANK_TRANSACTIONS'!$H$5:$H$168,"terceiros") -> 13500 | G26: 1 | H26: =F26*G26 -> 13500 | I26: NÃO RESIDENTE | J26: =IF(COUNTIFS('04_BANK_TRANSACTIONS'!$C$5:$C$168,2025,'04_BANK_TRANSACTIONS'!$E$5:$E$168,D26,'04_BANK_TRANSACTIONS'!$K$5:$K$168,"PENDENTE")>0,"Natureza PENDENTE — se renda de fonte BR: IRRF 15%/25%; se empréstimo/venda de bem/doação: tratamento próprio","Classificado na aba 04") -> Natureza PENDENTE — se renda de fonte BR: IRRF 15%/25%; se empréstimo/venda de bem/doação: tratamento próprio | K26: PENDENTE — DOCUMENTO NECESSÁRIO
A27: Extratos Nubank | B27: 2025 | C27: José | D27: ALEX SILVA DE SOUSA | E27: BRL | F27: =SUMIFS('04_BANK_TRANSACTIONS'!$F$5:$F$168,'04_BANK_TRANSACTIONS'!$C$5:$C$168,2025,'04_BANK_TRANSACTIONS'!$E$5:$E$168,D27,'04_BANK_TRANSACTIONS'!$G$5:$G$168,"entrada",'04_BANK_TRANSACTIONS'!$H$5:$H$168,"terceiros") -> 5870 | G27: 1 | H27: =F27*G27 -> 5870 | I27: NÃO RESIDENTE | J27: =IF(COUNTIFS('04_BANK_TRANSACTIONS'!$C$5:$C$168,2025,'04_BANK_TRANSACTIONS'!$E$5:$E$168,D27,'04_BANK_TRANSACTIONS'!$K$5:$K$168,"PENDENTE")>0,"Natureza PENDENTE — se renda de fonte BR: IRRF 15%/25%; se empréstimo/venda de bem/doação: tratamento próprio","Classificado na aba 04") -> Natureza PENDENTE — se renda de fonte BR: IRRF 15%/25%; se empréstimo/venda de bem/doação: tratamento próprio | K27: PENDENTE — DOCUMENTO NECESSÁRIO
A28: Extratos Nubank | B28: 2025 | C28: José | D28: DIEGO BRITO CORREIA | E28: BRL | F28: =SUMIFS('04_BANK_TRANSACTIONS'!$F$5:$F$168,'04_BANK_TRANSACTIONS'!$C$5:$C$168,2025,'04_BANK_TRANSACTIONS'!$E$5:$E$168,D28,'04_BANK_TRANSACTIONS'!$G$5:$G$168,"entrada",'04_BANK_TRANSACTIONS'!$H$5:$H$168,"terceiros") -> 5000 | G28: 1 | H28: =F28*G28 -> 5000 | I28: NÃO RESIDENTE | J28: =IF(COUNTIFS('04_BANK_TRANSACTIONS'!$C$5:$C$168,2025,'04_BANK_TRANSACTIONS'!$E$5:$E$168,D28,'04_BANK_TRANSACTIONS'!$K$5:$K$168,"PENDENTE")>0,"Natureza PENDENTE — se renda de fonte BR: IRRF 15%/25%; se empréstimo/venda de bem/doação: tratamento próprio","Classificado na aba 04") -> Natureza PENDENTE — se renda de fonte BR: IRRF 15%/25%; se empréstimo/venda de bem/doação: tratamento próprio | K28: PENDENTE — DOCUMENTO NECESSÁRIO
A29: Extratos Nubank | B29: 2025 | C29: José | D29: SANDRO DE ARAUJO MARRA | E29: BRL | F29: =SUMIFS('04_BANK_TRANSACTIONS'!$F$5:$F$168,'04_BANK_TRANSACTIONS'!$C$5:$C$168,2025,'04_BANK_TRANSACTIONS'!$E$5:$E$168,D29,'04_BANK_TRANSACTIONS'!$G$5:$G$168,"entrada",'04_BANK_TRANSACTIONS'!$H$5:$H$168,"terceiros") -> 1500 | G29: 1 | H29: =F29*G29 -> 1500 | I29: NÃO RESIDENTE | J29: =IF(COUNTIFS('04_BANK_TRANSACTIONS'!$C$5:$C$168,2025,'04_BANK_TRANSACTIONS'!$E$5:$E$168,D29,'04_BANK_TRANSACTIONS'!$K$5:$K$168,"PENDENTE")>0,"Natureza PENDENTE — se renda de fonte BR: IRRF 15%/25%; se empréstimo/venda de bem/doação: tratamento próprio","Classificado na aba 04") -> Natureza PENDENTE — se renda de fonte BR: IRRF 15%/25%; se empréstimo/venda de bem/doação: tratamento próprio | K29: PENDENTE — DOCUMENTO NECESSÁRIO
A30: Extratos Nubank | B30: 2025 | C30: José | D30: LEONARDO CARVALHO BARROS | E30: BRL | F30: =SUMIFS('04_BANK_TRANSACTIONS'!$F$5:$F$168,'04_BANK_TRANSACTIONS'!$C$5:$C$168,2025,'04_BANK_TRANSACTIONS'!$E$5:$E$168,D30,'04_BANK_TRANSACTIONS'!$G$5:$G$168,"entrada",'04_BANK_TRANSACTIONS'!$H$5:$H$168,"terceiros") -> 1000 | G30: 1 | H30: =F30*G30 -> 1000 | I30: NÃO RESIDENTE | J30: =IF(COUNTIFS('04_BANK_TRANSACTIONS'!$C$5:$C$168,2025,'04_BANK_TRANSACTIONS'!$E$5:$E$168,D30,'04_BANK_TRANSACTIONS'!$K$5:$K$168,"PENDENTE")>0,"Natureza PENDENTE — se renda de fonte BR: IRRF 15%/25%; se empréstimo/venda de bem/doação: tratamento próprio","Classificado na aba 04") -> Natureza PENDENTE — se renda de fonte BR: IRRF 15%/25%; se empréstimo/venda de bem/doação: tratamento próprio | K30: PENDENTE — DOCUMENTO NECESSÁRIO
... A32: Extratos Nubank | B32: 2025 | C32: José | D32: JOSIAS AMOREZE CARDOSO | E32: BRL | F32: =SUMIFS('04_BANK_TRANSACTIONS'!$F$5:$F$168,'04_BANK_TRANSACTIONS'!$C$5:$C$168,2025,'04_BANK_TRANSACTIONS'!$E$5:$E$168,D32,'04_BANK_TRANSACTIONS'!$G$5:$G$168,"entrada",'04_BANK_TRANSACTIONS'!$H$5:$H$168,"terceiros") -> 300 | G32: 1 | H32: =F32*G32 -> 300 | I32: NÃO RESIDENTE | J32: =IF(COUNTIFS('04_BANK_TRANSACTIONS'!$C$5:$C$168,2025,'04_BANK_TRANSACTIONS'!$E$5:$E$168,D32,'04_BANK_TRANSACTIONS'!$K$5:$K$168,"PENDENTE")>0,"Natureza PENDENTE — se renda de fonte BR: IRRF 15%/25%; se empréstimo/venda de bem/doação: tratamento próprio","Classificado na aba 04") -> Natureza PENDENTE — se renda de fonte BR: IRRF 15%/25%; se empréstimo/venda de bem/doação: tratamento próprio | K32: PENDENTE — DOCUMENTO NECESSÁRIO
A33: Extratos Nubank | B33: 2026 | C33: José | D33: LEONARDO CARVALHO BARROS | E33: BRL | F33: =SUMIFS('04_BANK_TRANSACTIONS'!$F$5:$F$168,'04_BANK_TRANSACTIONS'!$C$5:$C$168,2026,'04_BANK_TRANSACTIONS'!$E$5:$E$168,D33,'04_BANK_TRANSACTIONS'!$G$5:$G$168,"entrada",'04_BANK_TRANSACTIONS'!$H$5:$H$168,"terceiros") -> 8000 | G33: 1 | H33: =F33*G33 -> 8000 | I33: NÃO RESIDENTE | J33: =IF(COUNTIFS('04_BANK_TRANSACTIONS'!$C$5:$C$168,2026,'04_BANK_TRANSACTIONS'!$E$5:$E$168,D33,'04_BANK_TRANSACTIONS'!$K$5:$K$168,"PENDENTE")>0,"Natureza PENDENTE — se renda de fonte BR: IRRF 15%/25%; se empréstimo/venda de bem/doação: tratamento próprio","Classificado na aba 04") -> Natureza PENDENTE — se renda de fonte BR: IRRF 15%/25%; se empréstimo/venda de bem/doação: tratamento próprio | K33: PENDENTE — DOCUMENTO NECESSÁRIO
D34: TOTAL terceiros | H34: =SUM(H16:H33) -> 623510

Sheet 04_BANK_TRANSACTIONS
A1: 04 — MOVIMENTAÇÃO BANCÁRIA BRASIL (Nubank 89083502-4, out/2024–abr/2026) — classificação e IRRF
A2: José Adalmo Carvalho de Barros — CPF 069.351.996-70 | Resp. técnico: Robson Soares Bezerra — CRC/PR 062711/O
A3: Natureza: editar a coluna K (lista suspensa). IRRF apurado = só naturezas tributáveis. Cenários A/B = exposição máxima se a natureza PENDENTE fosse rendimento de fonte BR — NÃO é imposto devido. Vencimento do IRRF assumido na data do crédito [INFERÊNCIA TÉCNICA — confirmar]. Responsável legal pela retenção: a fonte pagadora [INFERÊNCIA TÉCNICA].
A4: ID | B4: Data | C4: Ano | D4: Descrição (extrato) | E4: Contraparte | F4: Valor BRL (+ entrada / − saída) | G4: Tipo | H4: Classe_7 (backup) | I4: Arquivo fonte | J4: Tratamento proposto | K4: Natureza (EDITAR) | L4: Material? | M4: Base ganho (só GCAP) | N4: Alíquota IRRF | O4: Base IRRF (só natureza tributável) | P4: IRRF apurado | Q4: Cenário A (15%) — só PENDENTE | R4: Cenário B (25%) — só PENDENTE | S4: Juros SELIC % | T4: Multa mora % | U4: IRRF apurado atualizado | V4: Cenário A atualizado | W4: Cenário B atualizado | X4: Vínculo imóvel
A5: 1 | B5: 45578 | C5: =YEAR(B5) -> 2024 | D5: Transferência recebida pelo Pix | BANCO DAYCOVAL SA REMITTANCE - 62.232.889 | /0001-90 - BCO DAYCOVAL S.A (0707) Agência: 1 | Conta: 1306-6 | E5: BANCO DAYCOVAL SA REMITTANCE | F5: 41475 | G5: entrada | H5: intermediario_remessa | I5: NU_890835024_01OUT2024_31OUT2024.pdf | J5: [HIPÓTESE] Remessa do exterior por instituição de câmbio — fonte estrangeira, fora do IRPF de não residente | K5: RECURSO_PROPRIO_EXTERIOR | L5: =IF(AND(G5="entrada",F5>='00_PARAMETROS'!$B$7),"SIM","NÃO") -> SIM | N5: {=IFERROR(INDEX('00_PARAMETROS'!$B$41:$B$54,MATCH(K5,'00_PARAMETROS'!$A$41:$A$54,0)),0)} -> 0 | O5: =IF(OR(G5<>"entrada",N5=0),0,IF(K5="VENDA_BEM_BR_GCAP",N(M5),F5)) -> 0 | P5: =ROUND(O5*N5,2) -> 0 | Q5: =IF(AND(G5="entrada",K5="PENDENTE"),ROUND(F5*'00_PARAMETROS'!$B$12,2),0) -> 0 | R5: =IF(AND(G5="entrada",K5="PENDENTE"),ROUND(F5*'00_PARAMETROS'!$B$13,2),0) -> 0 | S5: =IF(P5+Q5>0,SUMIFS(SELIC!$B$4:$B$96,SELIC!$A$4:$A$96,">="&DATE(YEAR(B5),MONTH(B5)+1,1),SELIC!$A$4:$A$96,"<="&DATE(YEAR('00_PARAMETROS'!$B$4),MONTH('00_PARAMETROS'!$B$4)-1,1))+'00_PARAMETROS'!$B$11,0) -> 0 | T5: =IF(P5+Q5>0,MIN('00_PARAMETROS'!$B$9,'00_PARAMETROS'!$B$8*MAX(0,'00_PARAMETROS'!$B$4-B5)),0) -> 0 | U5: =ROUND(P5*(1+S5+T5),2) -> 0 | V5: =ROUND(Q5*(1+S5+T5),2) -> 0 | W5: =ROUND(R5*(1+S5+T5),2) -> 0
A6: 2 | B6: 45578 | C6: =YEAR(B6) -> 2024 | D6: Aplicação RDB | E6: Aplicação RDB | F6: -41000 | G6: saida | H6: RDB | I6: NU_890835024_01OUT2024_31OUT2024.pdf | J6: Aplicação RDB (movimentação interna) | K6: SAIDA | L6: =IF(AND(G6="entrada",F6>='00_PARAMETROS'!$B$7),"SIM","NÃO") -> NÃO | N6: {=IFERROR(INDEX('00_PARAMETROS'!$B$41:$B$54,MATCH(K6,'00_PARAMETROS'!$A$41:$A$54,0)),0)} -> 0 | O6: =IF(OR(G6<>"entrada",N6=0),0,IF(K6="VENDA_BEM_BR_GCAP",N(M6),F6)) -> 0 | P6: =ROUND(O6*N6,2) -> 0 | Q6: =IF(AND(G6="entrada",K6="PENDENTE"),ROUND(F6*'00_PARAMETROS'!$B$12,2),0) -> 0 | R6: =IF(AND(G6="entrada",K6="PENDENTE"),ROUND(F6*'00_PARAMETROS'!$B$13,2),0) -> 0 | S6: =IF(P6+Q6>0,SUMIFS(SELIC!$B$4:$B$96,SELIC!$A$4:$A$96,">="&DATE(YEAR(B6),MONTH(B6)+1,1),SELIC!$A$4:$A$96,"<="&DATE(YEAR('00_PARAMETROS'!$B$4),MONTH('00_PARAMETROS'!$B$4)-1,1))+'00_PARAMETROS'!$B$11,0) -> 0 | T6: =IF(P6+Q6>0,MIN('00_PARAMETROS'!$B$9,'00_PARAMETROS'!$B$8*MAX(0,'00_PARAMETROS'!$B$4-B6)),0) -> 0 | U6: =ROUND(P6*(1+S6+T6),2) -> 0 | V6: =ROUND(Q6*(1+S6+T6),2) -> 0 | W6: =ROUND(R6*(1+S6+T6),2) -> 0
A7: 3 | B7: 45594 | C7: =YEAR(B7) -> 2024 | D7: Transferência enviada pelo Pix | Vitória Aparecida Carvalho de Barros - •••.947.926- | •• - CAIXA ECONOMICA FEDERAL (0104) Agência: | 108 Conta: 771878672-3 | E7: VITÓRIA APARECIDA CARVALHO DE BARROS | F7: -270 | G7: saida | H7: terceiros | I7: NU_890835024_01OUT2024_31OUT2024.pdf | J7: Débito — não é rendimento | K7: SAIDA | L7: =IF(AND(G7="entrada",F7>='00_PARAMETROS'!$B$7),"SIM","NÃO") -> NÃO | N7: {=IFERROR(INDEX('00_PARAMETROS'!$B$41:$B$54,MATCH(K7,'00_PARAMETROS'!$A$41:$A$54,0)),0)} -> 0 | O7: =IF(OR(G7<>"entrada",N7=0),0,IF(K7="VENDA_BEM_BR_GCAP",N(M7),F7)) -> 0 | P7: =ROUND(O7*N7,2) -> 0 | Q7: =IF(AND(G7="entrada",K7="PENDENTE"),ROUND(F7*'00_PARAMETROS'!$B$12,2),0) -> 0 | R7: =IF(AND(G7="entrada",K7="PENDENTE"),ROUND(F7*'00_PARAMETROS'!$B$13,2),0) -> 0 | S7: =IF(P7+Q7>0,SUMIFS(SELIC!$B$4:$B$96,SELIC!$A$4:$A$96,">="&DATE(YEAR(B7),MONTH(B7)+1,1),SELIC!$A$4:$A$96,"<="&DATE(YEAR('00_PARAMETROS'!$B$4),MONTH('00_PARAMETROS'!$B$4)-1,1))+'00_PARAMETROS'!$B$11,0) -> 0 | T7: =IF(P7+Q7>0,MIN('00_PARAMETROS'!$B$9,'00_PARAMETROS'!$B$8*MAX(0,'00_PARAMETROS'!$B$4-B7)),0) -> 0 | U7: =ROUND(P7*(1+S7+T7),2) -> 0 | V7: =ROUND(Q7*(1+S7+T7),2) -> 0 | W7: =ROUND(R7*(1+S7+T7),2) -> 0
A8: 4 | B8: 45595 | C8: =YEAR(B8) -> 2024 | D8: Transferência recebida pelo Pix | LEONARDO CARVALHO BARROS - •••.421.456-•• - | BCO DO BRASIL S.A. (0001) Agência: 25 Conta: | 510042852-6 | E8: LEONARDO CARVALHO BARROS | F8: 1000 | G8: entrada | H8: terceiros | I8: NU_890835024_01OUT2024_31OUT2024.pdf | J8: PENDENTE — DOCUMENTO NECESSÁRIO: natureza não comprovada (contrato, recibo, escritura, comprovante) | K8: PENDENTE | L8: =IF(AND(G8="entrada",F8>='00_PARAMETROS'!$B$7),"SIM","NÃO") -> NÃO | N8: {=IFERROR(INDEX('00_PARAMETROS'!$B$41:$B$54,MATCH(K8,'00_PARAMETROS'!$A$41:$A$54,0)),0)} -> 0 | O8: =IF(OR(G8<>"entrada",N8=0),0,IF(K8="VENDA_BEM_BR_GCAP",N(M8),F8)) -> 0 | P8: =ROUND(O8*N8,2) -> 0 | Q8: =IF(AND(G8="entrada",K8="PENDENTE"),ROUND(F8*'00_PARAMETROS'!$B$12,2),0) -> 150 | R8: =IF(AND(G8="entrada",K8="PENDENTE"),ROUND(F8*'00_PARAMETROS'!$B$13,2),0) -> 250 | S8: =IF(P8+Q8>0,SUMIFS(SELIC!$B$4:$B$96,SELIC!$A$4:$A$96,">="&DATE(YEAR(B8),MONTH(B8)+1,1),SELIC!$A$4:$A$96,"<="&DATE(YEAR('00_PARAMETROS'!$B$4),MONTH('00_PARAMETROS'!$B$4)-1,1))+'00_PARAMETROS'!$B$11,0) -> 0.2515 | T8: =IF(P8+Q8>0,MIN('00_PARAMETROS'!$B$9,'00_PARAMETROS'!$B$8*MAX(0,'00_PARAMETROS'!$B$4-B8)),0) -> 0.2 | U8: =ROUND(P8*(1+S8+T8),2) -> 0 | V8: =ROUND(Q8*(1+S8+T8),2) -> 217.73 | W8: =ROUND(R8*(1+S8+T8),2) -> 362.88
A9: 5 | B9: 45595 | C9: =YEAR(B9) -> 2024 | D9: Aplicação RDB | 89083502-4 | E9: 89083502-4 | F9: -1000 | G9: saida | H9: RDB | I9: NU_890835024_01OUT2024_31OUT2024.pdf | J9: Aplicação RDB (movimentação interna) | K9: SAIDA | L9: =IF(AND(G9="entrada",F9>='00_PARAMETROS'!$B$7),"SIM","NÃO") -> NÃO | N9: {=IFERROR(INDEX('00_PARAMETROS'!$B$41:$B$54,MATCH(K9,'00_PARAMETROS'!$A$41:$A$54,0)),0)} -> 0 | O9: =IF(OR(G9<>"entrada",N9=0),0,IF(K9="VENDA_BEM_BR_GCAP",N(M9),F9)) -> 0 | P9: =ROUND(O9*N9,2) -> 0 | Q9: =IF(AND(G9="entrada",K9="PENDENTE"),ROUND(F9*'00_PARAMETROS'!$B$12,2),0) -> 0 | R9: =IF(AND(G9="entrada",K9="PENDENTE"),ROUND(F9*'00_PARAMETROS'!$B$13,2),0) -> 0 | S9: =IF(P9+Q9>0,SUMIFS(SELIC!$B$4:$B$96,SELIC!$A$4:$A$96,">="&DATE(YEAR(B9),MONTH(B9)+1,1),SELIC!$A$4:$A$96,"<="&DATE(YEAR('00_PARAMETROS'!$B$4),MONTH('00_PARAMETROS'!$B$4)-1,1))+'00_PARAMETROS'!$B$11,0) -> 0 | T9: =IF(P9+Q9>0,MIN('00_PARAMETROS'!$B$9,'00_PARAMETROS'!$B$8*MAX(0,'00_PARAMETROS'!$B$4-B9)),0) -> 0 | U9: =ROUND(P9*(1+S9+T9),2) -> 0 | V9: =ROUND(Q9*(1+S9+T9),2) -> 0 | W9: =ROUND(R9*(1+S9+T9),2) -> 0
A10: 6 | B10: 45612 | C10: =YEAR(B10) -> 2024 | D10: Transferência recebida pelo Pix | FELIPE DE MELO RODRIGUES - •••.464.288-•• - ITAÚ | UNIBANCO S.A. (0341) Agência: 3247 Conta: | 40302-9 | E10: FELIPE DE MELO RODRIGUES | F10: 5000 | G10: entrada | H10: terceiros | I10: NU_890835024_01NOV2024_30NOV2024.pdf | J10: PENDENTE — DOCUMENTO NECESSÁRIO: natureza não comprovada (contrato, recibo, escritura, comprovante) | K10: PENDENTE | L10: =IF(AND(G10="entrada",F10>='00_PARAMETROS'!$B$7),"SIM","NÃO") -> NÃO | N10: {=IFERROR(INDEX('00_PARAMETROS'!$B$41:$B$54,MATCH(K10,'00_PARAMETROS'!$A$41:$A$54,0)),0)} -> 0 | O10: =IF(OR(G10<>"entrada",N10=0),0,IF(K10="VENDA_BEM_BR_GCAP",N(M10),F10)) -> 0 | P10: =ROUND(O10*N10,2) -> 0 | Q10: =IF(AND(G10="entrada",K10="PENDENTE"),ROUND(F10*'00_PARAMETROS'!$B$12,2),0) -> 750 | R10: =IF(AND(G10="entrada",K10="PENDENTE"),ROUND(F10*'00_PARAMETROS'!$B$13,2),0) -> 1250 | S10: =IF(P10+Q10>0,SUMIFS(SELIC!$B$4:$B$96,SELIC!$A$4:$A$96,">="&DATE(YEAR(B10),MONTH(B10)+1,1),SELIC!$A$4:$A$96,"<="&DATE(YEAR('00_PARAMETROS'!$B$4),MONTH('00_PARAMETROS'!$B$4)-1,1))+'00_PARAMETROS'!$B$11,0) -> 0.2436 | T10: =IF(P10+Q10>0,MIN('00_PARAMETROS'!$B$9,'00_PARAMETROS'!$B$8*MAX(0,'00_PARAMETROS'!$B$4-B10)),0) -> 0.2 | U10: =ROUND(P10*(1+S10+T10),2) -> 0 | V10: =ROUND(Q10*(1+S10+T10),2) -> 1082.7 | W10: =ROUND(R10*(1+S10+T10),2) -> 1804.5
A11: 7 | B11: 45612 | C11: =YEAR(B11) -> 2024 | D11: Transferência recebida pelo Pix | Felipe De Melo Rodrigues - •••.464.288-•• - NEON | PAGAMENTOS S.A. IP (0536) Agência: 655 Conta: | 23278478-7 | E11: FELIPE DE MELO RODRIGUES | F11: 8000 | G11: entrada | H11: terceiros | I11: NU_890835024_01NOV2024_30NOV2024.pdf | J11: PENDENTE — DOCUMENTO NECESSÁRIO: natureza não comprovada (contrato, recibo, escritura, comprovante) | K11: PENDENTE | L11: =IF(AND(G11="entrada",F11>='00_PARAMETROS'!$B$7),"SIM","NÃO") -> NÃO | N11: {=IFERROR(INDEX('00_PARAMETROS'!$B$41:$B$54,MATCH(K11,'00_PARAMETROS'!$A$41:$A$54,0)),0)} -> 0 | O11: =IF(OR(G11<>"entrada",N11=0),0,IF(K11="VENDA_BEM_BR_GCAP",N(M11),F11)) -> 0 | P11: =ROUND(O11*N11,2) -> 0 | Q11: =IF(AND(G11="entrada",K11="PENDENTE"),ROUND(F11*'00_PARAMETROS'!$B$12,2),0) -> 1200 | R11: =IF(AND(G11="entrada",K11="PENDENTE"),ROUND(F11*'00_PARAMETROS'!$B$13,2),0) -> 2000 | S11: =IF(P11+Q11>0,SUMIFS(SELIC!$B$4:$B$96,SELIC!$A$4:$A$96,">="&DATE(YEAR(B11),MONTH(B11)+1,1),SELIC!$A$4:$A$96,"<="&DATE(YEAR('00_PARAMETROS'!$B$4),MONTH('00_PARAMETROS'!$B$4)-1,1))+'00_PARAMETROS'!$B$11,0) -> 0.2436 | T11: =IF(P11+Q11>0,MIN('00_PARAMETROS'!$B$9,'00_PARAMETROS'!$B$8*MAX(0,'00_PARAMETROS'!$B$4-B11)),0) -> 0.2 | U11: =ROUND(P11*(1+S11+T11),2) -> 0 | V11: =ROUND(Q11*(1+S11+T11),2) -> 1732.32 | W11: =ROUND(R11*(1+S11+T11),2) -> 2887.2
A12: 8 | B12: 45612 | C12: =YEAR(B12) -> 2024 | D12: Transferência recebida pelo Pix | FELIPE DE MELO RODRIGUES - •••.464.288-•• - BCO | C6 S.A. (0336) Agência: 1 Conta: 15360860-9 | E12: FELIPE DE MELO RODRIGUES | F12: 3000 | G12: entrada | H12: terceiros | I12: NU_890835024_01NOV2024_30NOV2024.pdf | J12: PENDENTE — DOCUMENTO NECESSÁRIO: natureza não comprovada (contrato, recibo, escritura, comprovante) | K12: PENDENTE | L12: =IF(AND(G12="entrada",F12>='00_PARAMETROS'!$B$7),"SIM","NÃO") -> NÃO | N12: {=IFERROR(INDEX('00_PARAMETROS'!$B$41:$B$54,MATCH(K12,'00_PARAMETROS'!$A$41:$A$54,0)),0)} -> 0 | O12: =IF(OR(G12<>"entrada",N12=0),0,IF(K12="VENDA_BEM_BR_GCAP",N(M12),F12)) -> 0 | P12: =ROUND(O12*N12,2) -> 0 | Q12: =IF(AND(G12="entrada",K12="PENDENTE"),ROUND(F12*'00_PARAMETROS'!$B$12,2),0) -> 450 | R12: =IF(AND(G12="entrada",K12="PENDENTE"),ROUND(F12*'00_PARAMETROS'!$B$13,2),0) -> 750 | S12: =IF(P12+Q12>0,SUMIFS(SELIC!$B$4:$B$96,SELIC!$A$4:$A$96,">="&DATE(YEAR(B12),MONTH(B12)+1,1),SELIC!$A$4:$A$96,"<="&DATE(YEAR('00_PARAMETROS'!$B$4),MONTH('00_PARAMETROS'!$B$4)-1,1))+'00_PARAMETROS'!$B$11,0) -> 0.2436 | T12: =IF(P12+Q12>0,MIN('00_PARAMETROS'!$B$9,'00_PARAMETROS'!$B$8*MAX(0,'00_PARAMETROS'!$B$4-B12)),0) -> 0.2 | U12: =ROUND(P12*(1+S12+T12),2) -> 0 | V12: =ROUND(Q12*(1+S12+T12),2) -> 649.62 | W12: =ROUND(R12*(1+S12+T12),2) -> 1082.7
A13: 9 | B13: 45613 | C13: =YEAR(B13) -> 2024 | D13: Transferência recebida pelo Pix | FELIPE DE MELO RODRIGUES - •••.464.288-•• - ITAÚ | UNIBANCO S.A. (0341) Agência: 3247 Conta: | 40302-9 | E13: FELIPE DE MELO RODRIGUES | F13: 16000 | G13: entrada | H13: terceiros | I13: NU_890835024_01NOV2024_30NOV2024.pdf | J13: PENDENTE — DOCUMENTO NECESSÁRIO: natureza não comprovada (contrato, recibo, escritura, comprovante) | K13: PENDENTE | L13: =IF(AND(G13="entrada",F13>='00_PARAMETROS'!$B$7),"SIM","NÃO") -> SIM | N13: {=IFERROR(INDEX('00_PARAMETROS'!$B$41:$B$54,MATCH(K13,'00_PARAMETROS'!$A$41:$A$54,0)),0)} -> 0 | O13: =IF(OR(G13<>"entrada",N13=0),0,IF(K13="VENDA_BEM_BR_GCAP",N(M13),F13)) -> 0 | P13: =ROUND(O13*N13,2) -> 0 | Q13: =IF(AND(G13="entrada",K13="PENDENTE"),ROUND(F13*'00_PARAMETROS'!$B$12,2),0) -> 2400 | R13: =IF(AND(G13="entrada",K13="PENDENTE"),ROUND(F13*'00_PARAMETROS'!$B$13,2),0) -> 4000 | S13: =IF(P13+Q13>0,SUMIFS(SELIC!$B$4:$B$96,SELIC!$A$4:$A$96,">="&DATE(YEAR(B13),MONTH(B13)+1,1),SELIC!$A$4:$A$96,"<="&DATE(YEAR('00_PARAMETROS'!$B$4),MONTH('00_PARAMETROS'!$B$4)-1,1))+'00_PARAMETROS'!$B$11,0) -> 0.2436 | T13: =IF(P13+Q13>0,MIN('00_PARAMETROS'!$B$9,'00_PARAMETROS'!$B$8*MAX(0,'00_PARAMETROS'!$B$4-B13)),0) -> 0.2 | U13: =ROUND(P13*(1+S13+T13),2) -> 0 | V13: =ROUND(Q13*(1+S13+T13),2) -> 3464.64 | W13: =ROUND(R13*(1+S13+T13),2) -> 5774.4
A14: 10 | B14: 45613 | C14: =YEAR(B14) -> 2024 | D14: Transferência recebida pelo Pix | Felipe De Melo Rodrigues - •••.464.288-•• - NEON | PAGAMENTOS S.A. IP (0536) Agência: 655 Conta: | 23278478-7 | E14: FELIPE DE MELO RODRIGUES | F14: 8000 | G14: entrada | H14: terceiros | I14: NU_890835024_01NOV2024_30NOV2024.pdf | J14: PENDENTE — DOCUMENTO NECESSÁRIO: natureza não comprovada (contrato, recibo, escritura, comprovante) | K14: PENDENTE | L14: =IF(AND(G14="entrada",F14>='00_PARAMETROS'!$B$7),"SIM","NÃO") -> NÃO | N14: {=IFERROR(INDEX('00_PARAMETROS'!$B$41:$B$54,MATCH(K14,'00_PARAMETROS'!$A$41:$A$54,0)),0)} -> 0 | O14: =IF(OR(G14<>"entrada",N14=0),0,IF(K14="VENDA_BEM_BR_GCAP",N(M14),F14)) -> 0 | P14: =ROUND(O14*N14,2) -> 0 | Q14: =IF(AND(G14="entrada",K14="PENDENTE"),ROUND(F14*'00_PARAMETROS'!$B$12,2),0) -> 1200 | R14: =IF(AND(G14="entrada",K14="PENDENTE"),ROUND(F14*'00_PARAMETROS'!$B$13,2),0) -> 2000 | S14: =IF(P14+Q14>0,SUMIFS(SELIC!$B$4:$B$96,SELIC!$A$4:$A$96,">="&DATE(YEAR(B14),MONTH(B14)+1,1),SELIC!$A$4:$A$96,"<="&DATE(YEAR('00_PARAMETROS'!$B$4),MONTH('00_PARAMETROS'!$B$4)-1,1))+'00_PARAMETROS'!$B$11,0) -> 0.2436 | T14: =IF(P14+Q14>0,MIN('00_PARAMETROS'!$B$9,'00_PARAMETROS'!$B$8*MAX(0,'00_PARAMETROS'!$B$4-B14)),0) -> 0.2 | U14: =ROUND(P14*(1+S14+T14),2) -> 0 | V14: =ROUND(Q14*(1+S14+T14),2) -> 1732.32 | W14: =ROUND(R14*(1+S14+T14),2) -> 2887.2
A15: 11 | B15: 45614 | C15: =YEAR(B15) -> 2024 | D15: Transferência recebida pelo Pix | FELIPE DE MELO RODRIGUES - •••.464.288-•• - ITAÚ | UNIBANCO S.A. (0341) Agência: 3247 Conta: | 40302-9 | E15: FELIPE DE MELO RODRIGUES | F15: 4950 | G15: entrada | H15: terceiros | I15: NU_890835024_01NOV2024_30NOV2024.pdf | J15: PENDENTE — DOCUMENTO NECESSÁRIO: natureza não comprovada (contrato, recibo, escritura, comprovante) | K15: PENDENTE | L15: =IF(AND(G15="entrada",F15>='00_PARAMETROS'!$B$7),"SIM","NÃO") -> NÃO | N15: {=IFERROR(INDEX('00_PARAMETROS'!$B$41:$B$54,MATCH(K15,'00_PARAMETROS'!$A$41:$A$54,0)),0)} -> 0 | O15: =IF(OR(G15<>"entrada",N15=0),0,IF(K15="VENDA_BEM_BR_GCAP",N(M15),F15)) -> 0 | P15: =ROUND(O15*N15,2) -> 0 | Q15: =IF(AND(G15="entrada",K15="PENDENTE"),ROUND(F15*'00_PARAMETROS'!$B$12,2),0) -> 742.5 | R15: =IF(AND(G15="entrada",K15="PENDENTE"),ROUND(F15*'00_PARAMETROS'!$B$13,2),0) -> 1237.5 | S15: =IF(P15+Q15>0,SUMIFS(SELIC!$B$4:$B$96,SELIC!$A$4:$A$96,">="&DATE(YEAR(B15),MONTH(B15)+1,1),SELIC!$A$4:$A$96,"<="&DATE(YEAR('00_PARAMETROS'!$B$4),MONTH('00_PARAMETROS'!$B$4)-1,1))+'00_PARAMETROS'!$B$11,0) -> 0.2436 | T15: =IF(P15+Q15>0,MIN('00_PARAMETROS'!$B$9,'00_PARAMETROS'!$B$8*MAX(0,'00_PARAMETROS'!$B$4-B15)),0) -> 0.2 | U15: =ROUND(P15*(1+S15+T15),2) -> 0 | V15: =ROUND(Q15*(1+S15+T15),2) -> 1071.87 | W15: =ROUND(R15*(1+S15+T15),2) -> 1786.46
A16: 12 | B16: 45614 | C16: =YEAR(B16) -> 2024 | D16: Transferência enviada pelo Pix | Jasiel Greggio de Moraes - •••.117.228-•• - BCO DO | BRASIL S.A. (0001) Agência: 4094 Conta: 20226-6 | E16: JASIEL GREGGIO DE MORAES | F16: -200 | G16: saida | H16: terceiros | I16: NU_890835024_01NOV2024_30NOV2024.pdf | J16: Débito — não é rendimento | K16: SAIDA | L16: =IF(AND(G16="entrada",F16>='00_PARAMETROS'!$B$7),"SIM","NÃO") -> NÃO | N16: {=IFERROR(INDEX('00_PARAMETROS'!$B$41:$B$54,MATCH(K16,'00_PARAMETROS'!$A$41:$A$54,0)),0)} -> 0 | O16: =IF(OR(G16<>"entrada",N16=0),0,IF(K16="VENDA_BEM_BR_GCAP",N(M16),F16)) -> 0 | P16: =ROUND(O16*N16,2) -> 0 | Q16: =IF(AND(G16="entrada",K16="PENDENTE"),ROUND(F16*'00_PARAMETROS'!$B$12,2),0) -> 0 | R16: =IF(AND(G16="entrada",K16="PENDENTE"),ROUND(F16*'00_PARAMETROS'!$B$13,2),0) -> 0 | S16: =IF(P16+Q16>0,SUMIFS(SELIC!$B$4:$B$96,SELIC!$A$4:$A$96,">="&DATE(YEAR(B16),MONTH(B16)+1,1),SELIC!$A$4:$A$96,"<="&DATE(YEAR('00_PARAMETROS'!$B$4),MONTH('00_PARAMETROS'!$B$4)-1,1))+'00_PARAMETROS'!$B$11,0) -> 0 | T16: =IF(P16+Q16>0,MIN('00_PARAMETROS'!$B$9,'00_PARAMETROS'!$B$8*MAX(0,'00_PARAMETROS'!$B$4-B16)),0) -> 0 | U16: =ROUND(P16*(1+S16+T16),2) -> 0 | V16: =ROUND(Q16*(1+S16+T16),2) -> 0 | W16: =ROUND(R16*(1+S16+T16),2) -> 0
... A92: 88 | B92: 45866 | C92: =YEAR(B92) -> 2025 | D92: Transferência enviada pelo Pix | Adelio Joao Soares - •••.752.926-•• - BCO DO BRASIL | S.A. (0001) Agência: 25 Conta: 28854-3 | E92: ADELIO JOAO SOARES | F92: -150 | G92: saida | H92: terceiros | I92: 07.pdf | J92: Débito — não é rendimento | K92: SAIDA | L92: =IF(AND(G92="entrada",F92>='00_PARAMETROS'!$B$7),"SIM","NÃO") -> NÃO | N92: {=IFERROR(INDEX('00_PARAMETROS'!$B$41:$B$54,MATCH(K92,'00_PARAMETROS'!$A$41:$A$54,0)),0)} -> 0 | O92: =IF(OR(G92<>"entrada",N92=0),0,IF(K92="VENDA_BEM_BR_GCAP",N(M92),F92)) -> 0 | P92: =ROUND(O92*N92,2) -> 0 | Q92: =IF(AND(G92="entrada",K92="PENDENTE"),ROUND(F92*'00_PARAMETROS'!$B$12,2),0) -> 0 | R92: =IF(AND(G92="entrada",K92="PENDENTE"),ROUND(F92*'00_PARAMETROS'!$B$13,2),0) -> 0 | S92: =IF(P92+Q92>0,SUMIFS(SELIC!$B$4:$B$96,SELIC!$A$4:$A$96,">="&DATE(YEAR(B92),MONTH(B92)+1,1),SELIC!$A$4:$A$96,"<="&DATE(YEAR('00_PARAMETROS'!$B$4),MONTH('00_PARAMETROS'!$B$4)-1,1))+'00_PARAMETROS'!$B$11,0) -> 0 | T92: =IF(P92+Q92>0,MIN('00_PARAMETROS'!$B$9,'00_PARAMETROS'!$B$8*MAX(0,'00_PARAMETROS'!$B$4-B92)),0) -> 0 | U92: =ROUND(P92*(1+S92+T92),2) -> 0 | V92: =ROUND(Q92*(1+S92+T92),2) -> 0 | W92: =ROUND(R92*(1+S92+T92),2) -> 0
A93: 89 | B93: 45866 | C93: =YEAR(B93) -> 2025 | D93: Transferência enviada pelo Pix | N1 PORTO BELO EMPREENDIMENTOS - 43.796.362 | /0001-43 - CCLAA NOVA TRENTO Agência: 3242 | Conta: 72840-3 | E93: N1 PORTO BELO EMPREENDIMENTOS | F93: -5000 | G93: saida | H93: terceiros | I93: 07.pdf | J93: Pagamento — N1 Porto Belo / Vivapark [INFERÊNCIA — contrato indica conta VOKKAN] | K93: SAIDA | L93: =IF(AND(G93="entrada",F93>='00_PARAMETROS'!$B$7),"SIM","NÃO") -> NÃO | N93: {=IFERROR(INDEX('00_PARAMETROS'!$B$41:$B$54,MATCH(K93,'00_PARAMETROS'!$A$41:$A$54,0)),0)} -> 0 | O93: =IF(OR(G93<>"entrada",N93=0),0,IF(K93="VENDA_BEM_BR_GCAP",N(M93),F93)) -> 0 | P93: =ROUND(O93*N93,2) -> 0 | Q93: =IF(AND(G93="entrada",K93="PENDENTE"),ROUND(F93*'00_PARAMETROS'!$B$12,2),0) -> 0 | R93: =IF(AND(G93="entrada",K93="PENDENTE"),ROUND(F93*'00_PARAMETROS'!$B$13,2),0) -> 0 | S93: =IF(P93+Q93>0,SUMIFS(SELIC!$B$4:$B$96,SELIC!$A$4:$A$96,">="&DATE(YEAR(B93),MONTH(B93)+1,1),SELIC!$A$4:$A$96,"<="&DATE(YEAR('00_PARAMETROS'!$B$4),MONTH('00_PARAMETROS'!$B$4)-1,1))+'00_PARAMETROS'!$B$11,0) -> 0 | T93: =IF(P93+Q93>0,MIN('00_PARAMETROS'!$B$9,'00_PARAMETROS'!$B$8*MAX(0,'00_PARAMETROS'!$B$4-B93)),0) -> 0 | U93: =ROUND(P93*(1+S93+T93),2) -> 0 | V93: =ROUND(Q93*(1+S93+T93),2) -> 0 | W93: =ROUND(R93*(1+S93+T93),2) -> 0 | X93: N1 APTO 303
A94: 90 | B94: 45867 | C94: =YEAR(B94) -> 2025 | D94: Resgate RDB | E94: Resgate RDB | F94: 5000 | G94: entrada | H94: RDB | I94: 07.pdf | J94: [FATO CONFIRMADO] Resgate RDB — movimentação interna | K94: RDB_MOVIMENTACAO | L94: =IF(AND(G94="entrada",F94>='00_PARAMETROS'!$B$7),"SIM","NÃO") -> NÃO | N94: {=IFERROR(INDEX('00_PARAMETROS'!$B$41:$B$54,MATCH(K94,'00_PARAMETROS'!$A$41:$A$54,0)),0)} -> 0 | O94: =IF(OR(G94<>"entrada",N94=0),0,IF(K94="VENDA_BEM_BR_GCAP",N(M94),F94)) -> 0 | P94: =ROUND(O94*N94,2) -> 0 | Q94: =IF(AND(G94="entrada",K94="PENDENTE"),ROUND(F94*'00_PARAMETROS'!$B$12,2),0) -> 0 | R94: =IF(AND(G94="entrada",K94="PENDENTE"),ROUND(F94*'00_PARAMETROS'!$B$13,2),0) -> 0 | S94: =IF(P94+Q94>0,SUMIFS(SELIC!$B$4:$B$96,SELIC!$A$4:$A$96,">="&DATE(YEAR(B94),MONTH(B94)+1,1),SELIC!$A$4:$A$96,"<="&DATE(YEAR('00_PARAMETROS'!$B$4),MONTH('00_PARAMETROS'!$B$4)-1,1))+'00_PARAMETROS'!$B$11,0) -> 0 | T94: =IF(P94+Q94>0,MIN('00_PARAMETROS'!$B$9,'00_PARAMETROS'!$B$8*MAX(0,'00_PARAMETROS'!$B$4-B94)),0) -> 0 | U94: =ROUND(P94*(1+S94+T94),2) -> 0 | V94: =ROUND(Q94*(1+S94+T94),2) -> 0 | W94: =ROUND(R94*(1+S94+T94),2) -> 0
A95: 91 | B95: 45867 | C95: =YEAR(B95) -> 2025 | D95: Transferência recebida pelo Pix | WERSAN COMERCIO DE COMBUSTIVEIS LTDA - | 17.625.257/0001-31 - BCO SANTANDER (BRASIL) S. | 89083502-4 | A. (0033) Agência: 4278 Conta: 13001807-7 | E95: WERSAN COMERCIO DE COMBUSTIVEIS LTDA | F95: 49000 | G95: entrada | H95: terceiros | I95: 07.pdf | J95: PENDENTE — DOCUMENTO NECESSÁRIO: natureza não comprovada (contrato, recibo, escritura, comprovante) | K95: PENDENTE | L95: =IF(AND(G95="entrada",F95>='00_PARAMETROS'!$B$7),"SIM","NÃO") -> SIM | N95: {=IFERROR(INDEX('00_PARAMETROS'!$B$41:$B$54,MATCH(K95,'00_PARAMETROS'!$A$41:$A$54,0)),0)} -> 0 | O95: =IF(OR(G95<>"entrada",N95=0),0,IF(K95="VENDA_BEM_BR_GCAP",N(M95),F95)) -> 0 | P95: =ROUND(O95*N95,2) -> 0 | Q95: =IF(AND(G95="entrada",K95="PENDENTE"),ROUND(F95*'00_PARAMETROS'!$B$12,2),0) -> 7350 | R95: =IF(AND(G95="entrada",K95="PENDENTE"),ROUND(F95*'00_PARAMETROS'!$B$13,2),0) -> 12250 | S95: =IF(P95+Q95>0,SUMIFS(SELIC!$B$4:$B$96,SELIC!$A$4:$A$96,">="&DATE(YEAR(B95),MONTH(B95)+1,1),SELIC!$A$4:$A$96,"<="&DATE(YEAR('00_PARAMETROS'!$B$4),MONTH('00_PARAMETROS'!$B$4)-1,1))+'00_PARAMETROS'!$B$11,0) -> 0.1589 | T95: =IF(P95+Q95>0,MIN('00_PARAMETROS'!$B$9,'00_PARAMETROS'!$B$8*MAX(0,'00_PARAMETROS'!$B$4-B95)),0) -> 0.2 | U95: =ROUND(P95*(1+S95+T95),2) -> 0 | V95: =ROUND(Q95*(1+S95+T95),2) -> 9987.92 | W95: =ROUND(R95*(1+S95+T95),2) -> 16646.53
A96: 92 | B96: 45867 | C96: =YEAR(B96) -> 2025 | D96: Transferência enviada pelo Pix | Rofran Construtora Ltda - 51.819.924/0001-55 - | COOP SICREDI VALE LITORAL SC Agência: 2606 | Conta: 63110-5 | E96: ROFRAN CONSTRUTORA LTDA | F96: -5000 | G96: saida | H96: terceiros | I96: 07.pdf | J96: Pagamento — Loft 605 Blue Ocean (Rofran) | K96: SAIDA | L96: =IF(AND(G96="entrada",F96>='00_PARAMETROS'!$B$7),"SIM","NÃO") -> NÃO | N96: {=IFERROR(INDEX('00_PARAMETROS'!$B$41:$B$54,MATCH(K96,'00_PARAMETROS'!$A$41:$A$54,0)),0)} -> 0 | O96: =IF(OR(G96<>"entrada",N96=0),0,IF(K96="VENDA_BEM_BR_GCAP",N(M96),F96)) -> 0 | P96: =ROUND(O96*N96,2) -> 0 | Q96: =IF(AND(G96="entrada",K96="PENDENTE"),ROUND(F96*'00_PARAMETROS'!$B$12,2),0) -> 0 | R96: =IF(AND(G96="entrada",K96="PENDENTE"),ROUND(F96*'00_PARAMETROS'!$B$13,2),0) -> 0 | S96: =IF(P96+Q96>0,SUMIFS(SELIC!$B$4:$B$96,SELIC!$A$4:$A$96,">="&DATE(YEAR(B96),MONTH(B96)+1,1),SELIC!$A$4:$A$96,"<="&DATE(YEAR('00_PARAMETROS'!$B$4),MONTH('00_PARAMETROS'!$B$4)-1,1))+'00_PARAMETROS'!$B$11,0) -> 0 | T96: =IF(P96+Q96>0,MIN('00_PARAMETROS'!$B$9,'00_PARAMETROS'!$B$8*MAX(0,'00_PARAMETROS'!$B$4-B96)),0) -> 0 | U96: =ROUND(P96*(1+S96+T96),2) -> 0 | V96: =ROUND(Q96*(1+S96+T96),2) -> 0 | W96: =ROUND(R96*(1+S96+T96),2) -> 0 | X96: BLUE OCEAN 605
A97: 93 | B97: 45868 | C97: =YEAR(B97) -> 2025 | D97: Transferência recebida pelo Pix | ANDRE WERNER - •••.744.728-•• - ITAÚ UNIBANCO | S.A. (0341) Agência: 7012 Conta: 2282-3 | E97: ANDRE WERNER | F97: 51000 | G97: entrada | H97: terceiros | I97: 07.pdf | J97: PENDENTE — DOCUMENTO NECESSÁRIO: natureza não comprovada (contrato, recibo, escritura, comprovante) | K97: PENDENTE | L97: =IF(AND(G97="entrada",F97>='00_PARAMETROS'!$B$7),"SIM","NÃO") -> SIM | N97: {=IFERROR(INDEX('00_PARAMETROS'!$B$41:$B$54,MATCH(K97,'00_PARAMETROS'!$A$41:$A$54,0)),0)} -> 0 | O97: =IF(OR(G97<>"entrada",N97=0),0,IF(K97="VENDA_BEM_BR_GCAP",N(M97),F97)) -> 0 | P97: =ROUND(O97*N97,2) -> 0 | Q97: =IF(AND(G97="entrada",K97="PENDENTE"),ROUND(F97*'00_PARAMETROS'!$B$12,2),0) -> 7650 | R97: =IF(AND(G97="entrada",K97="PENDENTE"),ROUND(F97*'00_PARAMETROS'!$B$13,2),0) -> 12750 | S97: =IF(P97+Q97>0,SUMIFS(SELIC!$B$4:$B$96,SELIC!$A$4:$A$96,">="&DATE(YEAR(B97),MONTH(B97)+1,1),SELIC!$A$4:$A$96,"<="&DATE(YEAR('00_PARAMETROS'!$B$4),MONTH('00_PARAMETROS'!$B$4)-1,1))+'00_PARAMETROS'!$B$11,0) -> 0.1589 | T97: =IF(P97+Q97>0,MIN('00_PARAMETROS'!$B$9,'00_PARAMETROS'!$B$8*MAX(0,'00_PARAMETROS'!$B$4-B97)),0) -> 0.2 | U97: =ROUND(P97*(1+S97+T97),2) -> 0 | V97: =ROUND(Q97*(1+S97+T97),2) -> 10395.59 | W97: =ROUND(R97*(1+S97+T97),2) -> 17325.98
A98: 94 | B98: 45868 | C98: =YEAR(B98) -> 2025 | D98: Resgate RDB | E98: Resgate RDB | F98: 67269.32 | G98: entrada | H98: RDB | I98: 07.pdf | J98: [FATO CONFIRMADO] Resgate RDB — movimentação interna | K98: RDB_MOVIMENTACAO | L98: =IF(AND(G98="entrada",F98>='00_PARAMETROS'!$B$7),"SIM","NÃO") -> SIM | N98: {=IFERROR(INDEX('00_PARAMETROS'!$B$41:$B$54,MATCH(K98,'00_PARAMETROS'!$A$41:$A$54,0)),0)} -> 0 | O98: =IF(OR(G98<>"entrada",N98=0),0,IF(K98="VENDA_BEM_BR_GCAP",N(M98),F98)) -> 0 | P98: =ROUND(O98*N98,2) -> 0 | Q98: =IF(AND(G98="entrada",K98="PENDENTE"),ROUND(F98*'00_PARAMETROS'!$B$12,2),0) -> 0 | R98: =IF(AND(G98="entrada",K98="PENDENTE"),ROUND(F98*'00_PARAMETROS'!$B$13,2),0) -> 0 | S98: =IF(P98+Q98>0,SUMIFS(SELIC!$B$4:$B$96,SELIC!$A$4:$A$96,">="&DATE(YEAR(B98),MONTH(B98)+1,1),SELIC!$A$4:$A$96,"<="&DATE(YEAR('00_PARAMETROS'!$B$4),MONTH('00_PARAMETROS'!$B$4)-1,1))+'00_PARAMETROS'!$B$11,0) -> 0 | T98: =IF(P98+Q98>0,MIN('00_PARAMETROS'!$B$9,'00_PARAMETROS'!$B$8*MAX(0,'00_PARAMETROS'!$B$4-B98)),0) -> 0 | U98: =ROUND(P98*(1+S98+T98),2) -> 0 | V98: =ROUND(Q98*(1+S98+T98),2) -> 0 | W98: =ROUND(R98*(1+S98+T98),2) -> 0
A99: 95 | B99: 45868 | C99: =YEAR(B99) -> 2025 | D99: Transferência enviada pelo Pix | Vitória Aparecida Carvalho de Barros - •••.947.926- | •• - CAIXA ECONOMICA FEDERAL (0104) Agência: | 108 Conta: 771878672-3 | E99: VITÓRIA APARECIDA CARVALHO DE BARROS | F99: -392 | G99: saida | H99: terceiros | I99: 07.pdf | J99: Débito — não é rendimento | K99: SAIDA | L99: =IF(AND(G99="entrada",F99>='00_PARAMETROS'!$B$7),"SIM","NÃO") -> NÃO | N99: {=IFERROR(INDEX('00_PARAMETROS'!$B$41:$B$54,MATCH(K99,'00_PARAMETROS'!$A$41:$A$54,0)),0)} -> 0 | O99: =IF(OR(G99<>"entrada",N99=0),0,IF(K99="VENDA_BEM_BR_GCAP",N(M99),F99)) -> 0 | P99: =ROUND(O99*N99,2) -> 0 | Q99: =IF(AND(G99="entrada",K99="PENDENTE"),ROUND(F99*'00_PARAMETROS'!$B$12,2),0) -> 0 | R99: =IF(AND(G99="entrada",K99="PENDENTE"),ROUND(F99*'00_PARAMETROS'!$B$13,2),0) -> 0 | S99: =IF(P99+Q99>0,SUMIFS(SELIC!$B$4:$B$96,SELIC!$A$4:$A$96,">="&DATE(YEAR(B99),MONTH(B99)+1,1),SELIC!$A$4:$A$96,"<="&DATE(YEAR('00_PARAMETROS'!$B$4),MONTH('00_PARAMETROS'!$B$4)-1,1))+'00_PARAMETROS'!$B$11,0) -> 0 | T99: =IF(P99+Q99>0,MIN('00_PARAMETROS'!$B$9,'00_PARAMETROS'!$B$8*MAX(0,'00_PARAMETROS'!$B$4-B99)),0) -> 0 | U99: =ROUND(P99*(1+S99+T99),2) -> 0 | V99: =ROUND(Q99*(1+S99+T99),2) -> 0 | W99: =ROUND(R99*(1+S99+T99),2) -> 0
A100: 96 | B100: 45869 | C100: =YEAR(B100) -> 2025 | D100: Transferência enviada pelo Pix | N1 PORTO BELO EMPREENDIMENTOS - 43.796.362 | /0001-43 - CCLAA NOVA TRENTO Agência: 3242 | Conta: 72840-3 | 89083502-4 | E100: N1 PORTO BELO EMPREENDIMENTOS | F100: -40000 | G100: saida | H100: terceiros | I100: 07.pdf | J100: Pagamento — N1 Porto Belo / Vivapark [INFERÊNCIA — contrato indica conta VOKKAN] | K100: SAIDA | L100: =IF(AND(G100="entrada",F100>='00_PARAMETROS'!$B$7),"SIM","NÃO") -> NÃO | N100: {=IFERROR(INDEX('00_PARAMETROS'!$B$41:$B$54,MATCH(K100,'00_PARAMETROS'!$A$41:$A$54,0)),0)} -> 0 | O100: =IF(OR(G100<>"entrada",N100=0),0,IF(K100="VENDA_BEM_BR_GCAP",N(M100),F100)) -> 0 | P100: =ROUND(O100*N100,2) -> 0 | Q100: =IF(AND(G100="entrada",K100="PENDENTE"),ROUND(F100*'00_PARAMETROS'!$B$12,2),0) -> 0 | R100: =IF(AND(G100="entrada",K100="PENDENTE"),ROUND(F100*'00_PARAMETROS'!$B$13,2),0) -> 0 | S100: =IF(P100+Q100>0,SUMIFS(SELIC!$B$4:$B$96,SELIC!$A$4:$A$96,">="&DATE(YEAR(B100),MONTH(B100)+1,1),SELIC!$A$4:$A$96,"<="&DATE(YEAR('00_PARAMETROS'!$B$4),MONTH('00_PARAMETROS'!$B$4)-1,1))+'00_PARAMETROS'!$B$11,0) -> 0 | T100: =IF(P100+Q100>0,MIN('00_PARAMETROS'!$B$9,'00_PARAMETROS'!$B$8*MAX(0,'00_PARAMETROS'!$B$4-B100)),0) -> 0 | U100: =ROUND(P100*(1+S100+T100),2) -> 0 | V100: =ROUND(Q100*(1+S100+T100),2) -> 0 | W100: =ROUND(R100*(1+S100+T100),2) -> 0 | X100: N1 APTO 303
A101: 97 | B101: 45870 | C101: =YEAR(B101) -> 2025 | D101: Transferência enviada pelo Pix | Rofran Construtora Ltda - 51.819.924/0001-55 - | COOP SICREDI VALE LITORAL SC Agência: 2606 | Conta: 63110-5 | E101: ROFRAN CONSTRUTORA LTDA | F101: -45000 | G101: saida | H101: terceiros | I101: 08.pdf | J101: Pagamento — Loft 605 Blue Ocean (Rofran) | K101: SAIDA | L101: =IF(AND(G101="entrada",F101>='00_PARAMETROS'!$B$7),"SIM","NÃO") -> NÃO | N101: {=IFERROR(INDEX('00_PARAMETROS'!$B$41:$B$54,MATCH(K101,'00_PARAMETROS'!$A$41:$A$54,0)),0)} -> 0 | O101: =IF(OR(G101<>"entrada",N101=0),0,IF(K101="VENDA_BEM_BR_GCAP",N(M101),F101)) -> 0 | P101: =ROUND(O101*N101,2) -> 0 | Q101: =IF(AND(G101="entrada",K101="PENDENTE"),ROUND(F101*'00_PARAMETROS'!$B$12,2),0) -> 0 | R101: =IF(AND(G101="entrada",K101="PENDENTE"),ROUND(F101*'00_PARAMETROS'!$B$13,2),0) -> 0 | S101: =IF(P101+Q101>0,SUMIFS(SELIC!$B$4:$B$96,SELIC!$A$4:$A$96,">="&DATE(YEAR(B101),MONTH(B101)+1,1),SELIC!$A$4:$A$96,"<="&DATE(YEAR('00_PARAMETROS'!$B$4),MONTH('00_PARAMETROS'!$B$4)-1,1))+'00_PARAMETROS'!$B$11,0) -> 0 | T101: =IF(P101+Q101>0,MIN('00_PARAMETROS'!$B$9,'00_PARAMETROS'!$B$8*MAX(0,'00_PARAMETROS'!$B$4-B101)),0) -> 0 | U101: =ROUND(P101*(1+S101+T101),2) -> 0 | V101: =ROUND(Q101*(1+S101+T101),2) -> 0 | W101: =ROUND(R101*(1+S101+T101),2) -> 0 | X101: BLUE OCEAN 605
