Workbook

Sheet Resumo
A1: IRPF – José Adalmo Carvalho de Barros – Resumo
A2: CPF 069.351.996-70 | Responsável: Robson Soares Bezerra – Contador – CRC/PR 062711/O | Uso interno
A4: Data-base dos cálculos (altere aqui) | C4: 46201
A5: Imposto exigível hoje (R$) | C5: =F25 -> 0
A6: Exposição máxima – hipótese 1, 15% (R$) | C6: =H25 -> 125912.78
A7: Exposição máxima – hipótese 2, 25% (R$) | C7: =J25 -> 209854.59
A8: Recebimentos de terceiros sem origem comprovada (R$) | C8: =SUMIFS(Recebimentos!$D$5:$D$42,Recebimentos!$E$5:$E$42,"A comprovar") -> 623510
A9: Imóveis comprados em 2025 (R$) | C9: ='Imóveis e pendências'!D8 -> 1620265
A10: Imóveis: vencido sem comprovante de pagamento (R$) | C10: ='Imóveis e pendências'!D11 -> 219215
A12: Situação ano a ano
A13: Ano | B13: Situação no Brasil | C13: Receita pode cobrar até | D13: Prazo da Receita | E13: Imposto apurado (R$) | F13: Imposto exigível hoje (R$) | G13: Hipótese 1 – 15% (R$) | H13: Hipótese 1 – com juros e multa (R$) | I13: Hipótese 2 – 25% (R$) | J13: Hipótese 2 – com juros e multa (R$) | K13: Observação
A14: 2016 | B14: Morava no Brasil | C14: 44926 | D14: =IF($C$4>C14,"Vencido – não cobrável","Em aberto") -> Vencido – não cobrável | E14: 0 | F14: =IF(D14="Em aberto",E14,0) -> 0 | G14: =SUMIFS(Recebimentos!$F$5:$F$42,Recebimentos!$B$5:$B$42,A14) -> 0 | H14: =SUMIFS(Recebimentos!$J$5:$J$42,Recebimentos!$B$5:$B$42,A14) -> 0 | I14: =SUMIFS(Recebimentos!$G$5:$G$42,Recebimentos!$B$5:$B$42,A14) -> 0 | J14: =SUMIFS(Recebimentos!$K$5:$K$42,Recebimentos!$B$5:$B$42,A14) -> 0 | K14: Declaração entregue (recibo na pasta).
A15: 2017 | B15: Morava no Brasil | C15: 45291 | D15: =IF($C$4>C15,"Vencido – não cobrável","Em aberto") -> Vencido – não cobrável | E15: 0 | F15: =IF(D15="Em aberto",E15,0) -> 0 | G15: =SUMIFS(Recebimentos!$F$5:$F$42,Recebimentos!$B$5:$B$42,A15) -> 0 | H15: =SUMIFS(Recebimentos!$J$5:$J$42,Recebimentos!$B$5:$B$42,A15) -> 0 | I15: =SUMIFS(Recebimentos!$G$5:$G$42,Recebimentos!$B$5:$B$42,A15) -> 0 | J15: =SUMIFS(Recebimentos!$K$5:$K$42,Recebimentos!$B$5:$B$42,A15) -> 0 | K15: Entrega informada pelo cliente; recibo não localizado.
A16: 2018 | B16: Morava no Brasil | C16: 45657 | D16: =IF($C$4>C16,"Vencido – não cobrável","Em aberto") -> Vencido – não cobrável | E16: =B38 -> 10434.74 | F16: =IF(D16="Em aberto",E16,0) -> 0 | G16: =SUMIFS(Recebimentos!$F$5:$F$42,Recebimentos!$B$5:$B$42,A16) -> 0 | H16: =SUMIFS(Recebimentos!$J$5:$J$42,Recebimentos!$B$5:$B$42,A16) -> 0 | I16: =SUMIFS(Recebimentos!$G$5:$G$42,Recebimentos!$B$5:$B$42,A16) -> 0 | J16: =SUMIFS(Recebimentos!$K$5:$K$42,Recebimentos!$B$5:$B$42,A16) -> 0 | K16: Declaração obrigatória não entregue. Valor só informativo (quadro abaixo).
A17: 2019 | B17: Morava até 24/01; fora desde 25/01 | C17: 46022 | D17: =IF($C$4>C17,"Vencido – não cobrável","Em aberto") -> Vencido – não cobrável | E17: 0 | F17: =IF(D17="Em aberto",E17,0) -> 0 | G17: =SUMIFS(Recebimentos!$F$5:$F$42,Recebimentos!$B$5:$B$42,A17) -> 0 | H17: =SUMIFS(Recebimentos!$J$5:$J$42,Recebimentos!$B$5:$B$42,A17) -> 0 | I17: =SUMIFS(Recebimentos!$G$5:$G$42,Recebimentos!$B$5:$B$42,A17) -> 0 | J17: =SUMIFS(Recebimentos!$K$5:$K$42,Recebimentos!$B$5:$B$42,A17) -> 0 | K17: Renda no período abaixo do limite: sem imposto.
A18: 2020 | B18: Mora fora | C18: 46022 | D18: =IF($C$4>C18,"Vencido – não cobrável","Em aberto") -> Vencido – não cobrável | E18: 0 | F18: =IF(D18="Em aberto",E18,0) -> 0 | G18: =SUMIFS(Recebimentos!$F$5:$F$42,Recebimentos!$B$5:$B$42,A18) -> 0 | H18: =SUMIFS(Recebimentos!$J$5:$J$42,Recebimentos!$B$5:$B$42,A18) -> 0 | I18: =SUMIFS(Recebimentos!$G$5:$G$42,Recebimentos!$B$5:$B$42,A18) -> 0 | J18: =SUMIFS(Recebimentos!$K$5:$K$42,Recebimentos!$B$5:$B$42,A18) -> 0 | K18: Renda dos EUA não é tributada no Brasil.
A19: 2021 | B19: Mora fora | C19: 46387 | D19: =IF($C$4>C19,"Vencido – não cobrável","Em aberto") -> Em aberto | E19: 0 | F19: =IF(D19="Em aberto",E19,0) -> 0 | G19: =SUMIFS(Recebimentos!$F$5:$F$42,Recebimentos!$B$5:$B$42,A19) -> 0 | H19: =SUMIFS(Recebimentos!$J$5:$J$42,Recebimentos!$B$5:$B$42,A19) -> 0 | I19: =SUMIFS(Recebimentos!$G$5:$G$42,Recebimentos!$B$5:$B$42,A19) -> 0 | J19: =SUMIFS(Recebimentos!$K$5:$K$42,Recebimentos!$B$5:$B$42,A19) -> 0 | K19: Faltam extratos brasileiros. Prazo da Receita vence em dezembro.
A20: 2022 | B20: Mora fora | C20: 46752 | D20: =IF($C$4>C20,"Vencido – não cobrável","Em aberto") -> Em aberto | E20: 0 | F20: =IF(D20="Em aberto",E20,0) -> 0 | G20: =SUMIFS(Recebimentos!$F$5:$F$42,Recebimentos!$B$5:$B$42,A20) -> 0 | H20: =SUMIFS(Recebimentos!$J$5:$J$42,Recebimentos!$B$5:$B$42,A20) -> 0 | I20: =SUMIFS(Recebimentos!$G$5:$G$42,Recebimentos!$B$5:$B$42,A20) -> 0 | J20: =SUMIFS(Recebimentos!$K$5:$K$42,Recebimentos!$B$5:$B$42,A20) -> 0 | K20: Faltam extratos brasileiros.
A21: 2023 | B21: Mora fora | C21: 47118 | D21: =IF($C$4>C21,"Vencido – não cobrável","Em aberto") -> Em aberto | E21: 0 | F21: =IF(D21="Em aberto",E21,0) -> 0 | G21: =SUMIFS(Recebimentos!$F$5:$F$42,Recebimentos!$B$5:$B$42,A21) -> 0 | H21: =SUMIFS(Recebimentos!$J$5:$J$42,Recebimentos!$B$5:$B$42,A21) -> 0 | I21: =SUMIFS(Recebimentos!$G$5:$G$42,Recebimentos!$B$5:$B$42,A21) -> 0 | J21: =SUMIFS(Recebimentos!$K$5:$K$42,Recebimentos!$B$5:$B$42,A21) -> 0 | K21: Verificar criptomoedas (campo 'ativos digitais' = sim).
A22: 2024 | B22: Mora fora | C22: 47483 | D22: =IF($C$4>C22,"Vencido – não cobrável","Em aberto") -> Em aberto | E22: 0 | F22: =IF(D22="Em aberto",E22,0) -> 0 | G22: =SUMIFS(Recebimentos!$F$5:$F$42,Recebimentos!$B$5:$B$42,A22) -> 7117.5 | H22: =SUMIFS(Recebimentos!$J$5:$J$42,Recebimentos!$B$5:$B$42,A22) -> 10031.2 | I22: =SUMIFS(Recebimentos!$G$5:$G$42,Recebimentos!$B$5:$B$42,A22) -> 11862.5 | J22: =SUMIFS(Recebimentos!$K$5:$K$42,Recebimentos!$B$5:$B$42,A22) -> 16718.65 | K22: Recebimentos de terceiros a comprovar.
A23: 2025 | B23: Mora fora | C23: 47848 | D23: =IF($C$4>C23,"Vencido – não cobrável","Em aberto") -> Em aberto | E23: 0 | F23: =IF(D23="Em aberto",E23,0) -> 0 | G23: =SUMIFS(Recebimentos!$F$5:$F$42,Recebimentos!$B$5:$B$42,A23) -> 85209 | H23: =SUMIFS(Recebimentos!$J$5:$J$42,Recebimentos!$B$5:$B$42,A23) -> 114416.74 | I23: =SUMIFS(Recebimentos!$G$5:$G$42,Recebimentos!$B$5:$B$42,A23) -> 142015 | J23: =SUMIFS(Recebimentos!$K$5:$K$42,Recebimentos!$B$5:$B$42,A23) -> 190694.54 | K23: Terceiros a comprovar; imóveis; NÃO enviar a declaração gerada.
A24: 2026 | B24: Mora fora | C24: 48213 | D24: =IF($C$4>C24,"Vencido – não cobrável","Em aberto") -> Em aberto | E24: 0 | F24: =IF(D24="Em aberto",E24,0) -> 0 | G24: =SUMIFS(Recebimentos!$F$5:$F$42,Recebimentos!$B$5:$B$42,A24) -> 1200 | H24: =SUMIFS(Recebimentos!$J$5:$J$42,Recebimentos!$B$5:$B$42,A24) -> 1464.84 | I24: =SUMIFS(Recebimentos!$G$5:$G$42,Recebimentos!$B$5:$B$42,A24) -> 2000 | J24: =SUMIFS(Recebimentos!$K$5:$K$42,Recebimentos!$B$5:$B$42,A24) -> 2441.4 | K24: Até a data-base.
A25: TOTAL | E25: =SUM(E14:E24) -> 10434.74 | F25: =SUM(F14:F24) -> 0 | G25: =SUM(G14:G24) -> 93526.5 | H25: =SUM(H14:H24) -> 125912.78 | I25: =SUM(I14:I24) -> 155877.5 | J25: =SUM(J14:J24) -> 209854.59
A26: Hipótese = o que poderia ser cobrado SE os recebimentos de terceiros forem renda de fonte brasileira. Não é imposto devido. Enquanto a origem não for comprovada, nada é cobrado.
A29: Imposto de 2018 – cálculo informativo (a Receita não pode mais cobrar)
A30: Salário nos EUA em 2018 (US$ 25.628) convertido em reais | B30: 92634.55 | C30: Dólar de compra da 1ª quinzena do mês anterior; salário dividido em 12 parcelas iguais (premissa)
A31: Desconto simplificado | B31: =MIN(Taxas!$B$9*B30,Taxas!$B$10) -> 16754.34 | C31: 20% da renda, até o limite
A32: Base de cálculo | B32: =B30-B31 -> 75880.21
A33: Imposto pela tabela anual | B33: =ROUND(MAX(0,B32*LOOKUP(B32,Taxas!$A$14:$A$18,Taxas!$B$14:$B$18)-LOOKUP(B32,Taxas!$A$14:$A$18,Taxas!$C$14:$C$18)),2) -> 10434.74 | C33: O desconto simplificado é o mais vantajoso (o completo daria R$ 13.165,24)
A34: Imposto pago nos EUA que poderia abater | B34: 0 | C34: Imposto federal dos EUA em 2018 = US$ 0, então não há abatimento
A35: Juros (Selic) até a data-base | B35: =ROUND((B33-B34)*(SUMIFS(Taxas!$B$22:$B$110,Taxas!$A$22:$A$110,">="&DATE(2019,5,1),Taxas!$A$22:$A$110,"<="&DATE(YEAR(Resumo!$C$4),MONTH(Resumo!$C$4)-1,1))+Taxas!$B$6),2) -> 6809.71 | C35: Vencimento em 30/04/2019
A36: Multa por atraso | B36: =ROUND((B33-B34)*MIN(Taxas!$B$5,Taxas!$B$4*MAX(0,$C$4-DATE(2019,4,30))),2) -> 2086.95 | C36: Limite de 20%
A37: Total teórico atualizado | B37: =B33-B34+B35+B36 -> 19331.4 | C37: Só informativo
A38: Imposto de 2018 (sem juros e multa) | B38: =B33-B34 -> 10434.74 | C38: Usado na tabela acima
A41: Renda e imposto nos EUA (informativo, em US$) – não é tributada no Brasil desde que mora fora
A42: Ano | B42: Tipo de renda | C42: Receita | D42: Lucro | E42: Imposto de renda federal | F42: Contribuição previdenciária de autônomo | G42: Observação
A43: 2018 | B43: Salário (empregado) | C43: 25628 | E43: 0 | F43: 0 | G43: Imposto de US$ 164 zerado pelo crédito por filhos.
A44: 2019 | B44: Atividade autônoma | C44: 10000 | D44: 10000 | E44: 0 | F44: 1413
A45: 2020 | B45: Atividade autônoma | C45: 30152 | D45: 2252 | E45: 0 | F45: 318
A46: 2021 | B46: Atividade autônoma | C46: 35335 | D46: 4870 | E46: 0 | F46: 686
...

Sheet Recebimentos
A1: Recebimentos de terceiros no Brasil sem origem comprovada (conta Nubank, out/2024 a abr/2026)
A2: Se a origem for comprovada (empréstimo, venda de bem, recurso próprio, doação), troque 'A comprovar' pelo tipo: a linha sai da exposição.
A4: Data | B4: Ano | C4: Quem enviou | D4: Valor (R$) | E4: Origem (preencher) | F4: Hipótese 1 – imposto (15%) | G4: Hipótese 2 – imposto (25%) | H4: Juros (Selic) | I4: Multa por atraso | J4: Hipótese 1 – com juros e multa | K4: Hipótese 2 – com juros e multa
A5: 45595 | B5: =YEAR(A5) -> 2024 | C5: Leonardo Carvalho Barros | D5: 1000 | E5: A comprovar | F5: =IF(E5="A comprovar",ROUND(D5*Taxas!$B$7,2),0) -> 150 | G5: =IF(E5="A comprovar",ROUND(D5*Taxas!$B$8,2),0) -> 250 | H5: =IF(F5>0,SUMIFS(Taxas!$B$22:$B$110,Taxas!$A$22:$A$110,">="&DATE(YEAR(A5),MONTH(A5)+1,1),Taxas!$A$22:$A$110,"<="&DATE(YEAR(Resumo!$C$4),MONTH(Resumo!$C$4)-1,1))+Taxas!$B$6,0) -> 0.2172 | I5: =IF(F5>0,MIN(Taxas!$B$5,Taxas!$B$4*MAX(0,Resumo!$C$4-A5)),0) -> 0.2 | J5: =ROUND(F5*(1+H5+I5),2) -> 212.58 | K5: =ROUND(G5*(1+H5+I5),2) -> 354.3
A6: 45612 | B6: =YEAR(A6) -> 2024 | C6: Felipe De Melo Rodrigues | D6: 5000 | E6: A comprovar | F6: =IF(E6="A comprovar",ROUND(D6*Taxas!$B$7,2),0) -> 750 | G6: =IF(E6="A comprovar",ROUND(D6*Taxas!$B$8,2),0) -> 1250 | H6: =IF(F6>0,SUMIFS(Taxas!$B$22:$B$110,Taxas!$A$22:$A$110,">="&DATE(YEAR(A6),MONTH(A6)+1,1),Taxas!$A$22:$A$110,"<="&DATE(YEAR(Resumo!$C$4),MONTH(Resumo!$C$4)-1,1))+Taxas!$B$6,0) -> 0.2093 | I6: =IF(F6>0,MIN(Taxas!$B$5,Taxas!$B$4*MAX(0,Resumo!$C$4-A6)),0) -> 0.2 | J6: =ROUND(F6*(1+H6+I6),2) -> 1056.98 | K6: =ROUND(G6*(1+H6+I6),2) -> 1761.63
A7: 45612 | B7: =YEAR(A7) -> 2024 | C7: Felipe De Melo Rodrigues | D7: 8000 | E7: A comprovar | F7: =IF(E7="A comprovar",ROUND(D7*Taxas!$B$7,2),0) -> 1200 | G7: =IF(E7="A comprovar",ROUND(D7*Taxas!$B$8,2),0) -> 2000 | H7: =IF(F7>0,SUMIFS(Taxas!$B$22:$B$110,Taxas!$A$22:$A$110,">="&DATE(YEAR(A7),MONTH(A7)+1,1),Taxas!$A$22:$A$110,"<="&DATE(YEAR(Resumo!$C$4),MONTH(Resumo!$C$4)-1,1))+Taxas!$B$6,0) -> 0.2093 | I7: =IF(F7>0,MIN(Taxas!$B$5,Taxas!$B$4*MAX(0,Resumo!$C$4-A7)),0) -> 0.2 | J7: =ROUND(F7*(1+H7+I7),2) -> 1691.16 | K7: =ROUND(G7*(1+H7+I7),2) -> 2818.6
A8: 45612 | B8: =YEAR(A8) -> 2024 | C8: Felipe De Melo Rodrigues | D8: 3000 | E8: A comprovar | F8: =IF(E8="A comprovar",ROUND(D8*Taxas!$B$7,2),0) -> 450 | G8: =IF(E8="A comprovar",ROUND(D8*Taxas!$B$8,2),0) -> 750 | H8: =IF(F8>0,SUMIFS(Taxas!$B$22:$B$110,Taxas!$A$22:$A$110,">="&DATE(YEAR(A8),MONTH(A8)+1,1),Taxas!$A$22:$A$110,"<="&DATE(YEAR(Resumo!$C$4),MONTH(Resumo!$C$4)-1,1))+Taxas!$B$6,0) -> 0.2093 | I8: =IF(F8>0,MIN(Taxas!$B$5,Taxas!$B$4*MAX(0,Resumo!$C$4-A8)),0) -> 0.2 | J8: =ROUND(F8*(1+H8+I8),2) -> 634.19 | K8: =ROUND(G8*(1+H8+I8),2) -> 1056.98
A9: 45613 | B9: =YEAR(A9) -> 2024 | C9: Felipe De Melo Rodrigues | D9: 16000 | E9: A comprovar | F9: =IF(E9="A comprovar",ROUND(D9*Taxas!$B$7,2),0) -> 2400 | G9: =IF(E9="A comprovar",ROUND(D9*Taxas!$B$8,2),0) -> 4000 | H9: =IF(F9>0,SUMIFS(Taxas!$B$22:$B$110,Taxas!$A$22:$A$110,">="&DATE(YEAR(A9),MONTH(A9)+1,1),Taxas!$A$22:$A$110,"<="&DATE(YEAR(Resumo!$C$4),MONTH(Resumo!$C$4)-1,1))+Taxas!$B$6,0) -> 0.2093 | I9: =IF(F9>0,MIN(Taxas!$B$5,Taxas!$B$4*MAX(0,Resumo!$C$4-A9)),0) -> 0.2 | J9: =ROUND(F9*(1+H9+I9),2) -> 3382.32 | K9: =ROUND(G9*(1+H9+I9),2) -> 5637.2
A10: 45613 | B10: =YEAR(A10) -> 2024 | C10: Felipe De Melo Rodrigues | D10: 8000 | E10: A comprovar | F10: =IF(E10="A comprovar",ROUND(D10*Taxas!$B$7,2),0) -> 1200 | G10: =IF(E10="A comprovar",ROUND(D10*Taxas!$B$8,2),0) -> 2000 | H10: =IF(F10>0,SUMIFS(Taxas!$B$22:$B$110,Taxas!$A$22:$A$110,">="&DATE(YEAR(A10),MONTH(A10)+1,1),Taxas!$A$22:$A$110,"<="&DATE(YEAR(Resumo!$C$4),MONTH(Resumo!$C$4)-1,1))+Taxas!$B$6,0) -> 0.2093 | I10: =IF(F10>0,MIN(Taxas!$B$5,Taxas!$B$4*MAX(0,Resumo!$C$4-A10)),0) -> 0.2 | J10: =ROUND(F10*(1+H10+I10),2) -> 1691.16 | K10: =ROUND(G10*(1+H10+I10),2) -> 2818.6
A11: 45614 | B11: =YEAR(A11) -> 2024 | C11: Felipe De Melo Rodrigues | D11: 4950 | E11: A comprovar | F11: =IF(E11="A comprovar",ROUND(D11*Taxas!$B$7,2),0) -> 742.5 | G11: =IF(E11="A comprovar",ROUND(D11*Taxas!$B$8,2),0) -> 1237.5 | H11: =IF(F11>0,SUMIFS(Taxas!$B$22:$B$110,Taxas!$A$22:$A$110,">="&DATE(YEAR(A11),MONTH(A11)+1,1),Taxas!$A$22:$A$110,"<="&DATE(YEAR(Resumo!$C$4),MONTH(Resumo!$C$4)-1,1))+Taxas!$B$6,0) -> 0.2093 | I11: =IF(F11>0,MIN(Taxas!$B$5,Taxas!$B$4*MAX(0,Resumo!$C$4-A11)),0) -> 0.2 | J11: =ROUND(F11*(1+H11+I11),2) -> 1046.41 | K11: =ROUND(G11*(1+H11+I11),2) -> 1744.01
A12: 45625 | B12: =YEAR(A12) -> 2024 | C12: Diego Novais De Melo Fonseca | D12: 1000 | E12: A comprovar | F12: =IF(E12="A comprovar",ROUND(D12*Taxas!$B$7,2),0) -> 150 | G12: =IF(E12="A comprovar",ROUND(D12*Taxas!$B$8,2),0) -> 250 | H12: =IF(F12>0,SUMIFS(Taxas!$B$22:$B$110,Taxas!$A$22:$A$110,">="&DATE(YEAR(A12),MONTH(A12)+1,1),Taxas!$A$22:$A$110,"<="&DATE(YEAR(Resumo!$C$4),MONTH(Resumo!$C$4)-1,1))+Taxas!$B$6,0) -> 0.2093 | I12: =IF(F12>0,MIN(Taxas!$B$5,Taxas!$B$4*MAX(0,Resumo!$C$4-A12)),0) -> 0.2 | J12: =ROUND(F12*(1+H12+I12),2) -> 211.4 | K12: =ROUND(G12*(1+H12+I12),2) -> 352.33
A13: 45631 | B13: =YEAR(A13) -> 2024 | C13: Leonardo Carvalho Barros | D13: 500 | E13: A comprovar | F13: =IF(E13="A comprovar",ROUND(D13*Taxas!$B$7,2),0) -> 75 | G13: =IF(E13="A comprovar",ROUND(D13*Taxas!$B$8,2),0) -> 125 | H13: =IF(F13>0,SUMIFS(Taxas!$B$22:$B$110,Taxas!$A$22:$A$110,">="&DATE(YEAR(A13),MONTH(A13)+1,1),Taxas!$A$22:$A$110,"<="&DATE(YEAR(Resumo!$C$4),MONTH(Resumo!$C$4)-1,1))+Taxas!$B$6,0) -> 0.2 | I13: =IF(F13>0,MIN(Taxas!$B$5,Taxas!$B$4*MAX(0,Resumo!$C$4-A13)),0) -> 0.2 | J13: =ROUND(F13*(1+H13+I13),2) -> 105 | K13: =ROUND(G13*(1+H13+I13),2) -> 175
A14: 45665 | B14: =YEAR(A14) -> 2025 | C14: Diego Novais De Melo Fonseca | D14: 1000 | E14: A comprovar | F14: =IF(E14="A comprovar",ROUND(D14*Taxas!$B$7,2),0) -> 150 | G14: =IF(E14="A comprovar",ROUND(D14*Taxas!$B$8,2),0) -> 250 | H14: =IF(F14>0,SUMIFS(Taxas!$B$22:$B$110,Taxas!$A$22:$A$110,">="&DATE(YEAR(A14),MONTH(A14)+1,1),Taxas!$A$22:$A$110,"<="&DATE(YEAR(Resumo!$C$4),MONTH(Resumo!$C$4)-1,1))+Taxas!$B$6,0) -> 0.1899 | I14: =IF(F14>0,MIN(Taxas!$B$5,Taxas!$B$4*MAX(0,Resumo!$C$4-A14)),0) -> 0.2 | J14: =ROUND(F14*(1+H14+I14),2) -> 208.49 | K14: =ROUND(G14*(1+H14+I14),2) -> 347.48
A15: 45673 | B15: =YEAR(A15) -> 2025 | C15: Josias Amoreze Cardoso | D15: 300 | E15: A comprovar | F15: =IF(E15="A comprovar",ROUND(D15*Taxas!$B$7,2),0) -> 45 | G15: =IF(E15="A comprovar",ROUND(D15*Taxas!$B$8,2),0) -> 75 | H15: =IF(F15>0,SUMIFS(Taxas!$B$22:$B$110,Taxas!$A$22:$A$110,">="&DATE(YEAR(A15),MONTH(A15)+1,1),Taxas!$A$22:$A$110,"<="&DATE(YEAR(Resumo!$C$4),MONTH(Resumo!$C$4)-1,1))+Taxas!$B$6,0) -> 0.1899 | I15: =IF(F15>0,MIN(Taxas!$B$5,Taxas!$B$4*MAX(0,Resumo!$C$4-A15)),0) -> 0.2 | J15: =ROUND(F15*(1+H15+I15),2) -> 62.55 | K15: =ROUND(G15*(1+H15+I15),2) -> 104.24
A16: 45677 | B16: =YEAR(A16) -> 2025 | C16: Leonardo Carvalho Barros | D16: 500 | E16: A comprovar | F16: =IF(E16="A comprovar",ROUND(D16*Taxas!$B$7,2),0) -> 75 | G16: =IF(E16="A comprovar",ROUND(D16*Taxas!$B$8,2),0) -> 125 | H16: =IF(F16>0,SUMIFS(Taxas!$B$22:$B$110,Taxas!$A$22:$A$110,">="&DATE(YEAR(A16),MONTH(A16)+1,1),Taxas!$A$22:$A$110,"<="&DATE(YEAR(Resumo!$C$4),MONTH(Resumo!$C$4)-1,1))+Taxas!$B$6,0) -> 0.1899 | I16: =IF(F16>0,MIN(Taxas!$B$5,Taxas!$B$4*MAX(0,Resumo!$C$4-A16)),0) -> 0.2 | J16: =ROUND(F16*(1+H16+I16),2) -> 104.24 | K16: =ROUND(G16*(1+H16+I16),2) -> 173.74
... A42: 46125 | B42: =YEAR(A42) -> 2026 | C42: Leonardo Carvalho Barros | D42: 8000 | E42: A comprovar | F42: =IF(E42="A comprovar",ROUND(D42*Taxas!$B$7,2),0) -> 1200 | G42: =IF(E42="A comprovar",ROUND(D42*Taxas!$B$8,2),0) -> 2000 | H42: =IF(F42>0,SUMIFS(Taxas!$B$22:$B$110,Taxas!$A$22:$A$110,">="&DATE(YEAR(A42),MONTH(A42)+1,1),Taxas!$A$22:$A$110,"<="&DATE(YEAR(Resumo!$C$4),MONTH(Resumo!$C$4)-1,1))+Taxas!$B$6,0) -> 0.0207 | I42: =IF(F42>0,MIN(Taxas!$B$5,Taxas!$B$4*MAX(0,Resumo!$C$4-A42)),0) -> 0.2 | J42: =ROUND(F42*(1+H42+I42),2) -> 1464.84 | K42: =ROUND(G42*(1+H42+I42),2) -> 2441.4
A43: TOTAL | D43: =SUM(D5:D42) -> 623510 | F43: =SUM(F5:F42) -> 93526.5 | G43: =SUM(G5:G42) -> 155877.5 | J43: =SUM(J5:J42) -> 125912.78 | K43: =SUM(K5:K42) -> 209854.59

Sheet Imóveis e pendências
A1: Imóveis comprados em 2025 e pendências
A2: Valores em R$.
A3: Item | B3: Blue Ocean – Loft 605 | C3: N1 Porto Belo – Apto 303 | D3: Total
A4: Contrato | B4: 30/07/2025 | C4: 30/07/2025
A5: Quem comprou | B5: José (casado com Márcia) | C5: José e Márcia
A6: Endereço de moradia escrito no contrato | B6: Goioerê/PR (Brasil) | C6: Bethel/CT (EUA)
A7: Observação | B7: Contradiz a condição de quem mora fora
A8: Preço contratado | B8: 370000 | C8: 1250265 | D8: =B8+C8 -> 1620265
A9: Vencido até 31/12/2025 | B9: 370000 | C9: 193415 | D9: =B9+C9 -> 563415
A10: Pago pela conta Nubank (comprovado) | B10: 295000 | C10: 49200 | D10: =B10+C10 -> 344200
A11: Vencido sem comprovante de pagamento | B11: =B9-B10 -> 75000 | C11: =C9-C10 -> 144215 | D11: =B11+C11 -> 219215
A12: Ainda a vencer (a partir de 2026) | B12: 0 | C12: 1056850 | D12: =B12+C12 -> 1056850
A14: De onde veio o dinheiro que entrou na conta Nubank em 2025
A15: Origem | B15: Valor (R$) | C15: Quantidade
A16: Remessas do exterior (Daycoval, Remitly, TAPTAP) | B16: 133096.7 | C16: 14
A17: Terceiros no Brasil – origem a comprovar | B17: 568060 | C17: 28
A18: Transferências da esposa | B18: 85000 | C18: 2
A19: Resgates de aplicação (dinheiro já da conta) | B19: 89277.35 | C19: 14
A20: Estornos | B20: 900 | C20: 1
A21: Total que entrou em 2025 | B21: =SUM(B16:B20) -> 876334.05 | C21: =SUM(C16:C20) -> 59
A23: O que fazer (por prioridade)
A24: O que está pendente | B24: Nível | C24: O que fazer | D24: Prazo
A25: Arquivo da declaração de 2026 com endereço em São Paulo | B25: Crítico | C25: NÃO enviar. Guardar com nota técnica. | D25: Imediato
A26: Recebimentos de terceiros sem origem comprovada (R$ 623.510) | B26: Alto | C26: Contrato, recibo, escritura ou declaração de quem pagou, para cada valor. | D26: 30/10/2026
A27: Data de saída do Brasil (25/01/2018) sem prova em nome do José | B27: Alto | C27: Passaporte, I-94, passagens, carteira de motorista de CT, aluguel em seu nome. | D27: 30/10/2026
A28: Contrato Blue Ocean diz que mora em Goioerê/PR | B28: Alto | C28: Corrigir por aditivo ou na escritura; reunir provas de moradia nos EUA. | D28: Antes da escritura
A29: R$ 219.215 de imóveis sem comprovante de pagamento | B29: Alto | C29: Extratos das contas usadas (esposa, outras, exterior). | D29: 30/11/2026
A30: Extratos que faltam (abr–mai/2025, mar/2026 e 2019 a 2023) | B30: Médio | C30: Pedir extratos completos de todas as contas no Brasil. | D30: 30/11/2026
A31: Criptomoedas em 2023 (campo 'ativos digitais' = sim) | B31: Médio | C31: Informar plataformas e se houve lucro; se for plataforma brasileira, pode haver imposto. | D31: 30/11/2026
A32: Remessas do exterior (R$ 180.971,76, 18 operações) | B32: Médio | C32: Reunir contratos de câmbio ou comprovantes de quem enviou. | D32: 30/11/2026
A33: Imposto de 2024 nos EUA (US$ 6.963) sem comprovante de pagamento | B33: Médio | C33: Comprovar o pagamento (não afeta o Brasil). | D33: —
A34: CPF ainda como morador do Brasil; conta de residente | B34: Médio | C34: Atualizar o CPF como morador no exterior e nomear procurador no Brasil. | D34: 31/12/2026
A35: Situação fiscal da esposa (Márcia) não analisada | B35: Médio | C35: Fazer a mesma análise e comprovar a origem dos R$ 85.000 enviados. | D35: 30/11/2026
A36: Participação em 3 sociedades nos EUA | B36: Baixo | C36: Provavelmente sem obrigação de declarar ao Banco Central por morar fora (confirmar). | D36: —

Sheet Taxas
A1: Taxas e regras usadas nos cálculos
A2: Células amarelas com letra azul podem ser alteradas.
A3: Regra | B3: Valor | C3: Observação
A4: Multa por dia de atraso | B4: 0.0033 | C4: Lei 9.430/1996, art. 61 (confirmar na fonte oficial)
A5: Limite da multa | B5: 0.2 | C5: Máximo de 20%
A6: Juros extra no mês do pagamento | B6: 0.01 | C6: Somado à taxa Selic acumulada
A7: Imposto retido na fonte – hipótese 1 | B7: 0.15 | C7: Regra geral para quem mora fora (confirmar)
A8: Imposto retido na fonte – hipótese 2 | B8: 0.25 | C8: Trabalho/serviços para quem mora fora (confirmar)
A9: Desconto simplificado (2018) | B9: 0.2 | C9: 20% da renda, com limite abaixo
A10: Limite do desconto simplificado (2018) | B10: 16754.34 | C10: Confirmar na fonte oficial
A12: Tabela do imposto sobre a renda – ano de 2018 (anual)
A13: Renda a partir de (R$) | B13: Alíquota | C13: Parcela a deduzir (R$)
A14: 0 | B14: 0 | C14: 0
A15: 22847.77 | B15: 0.075 | C15: 1713.58
A16: 33919.81 | B16: 0.15 | C16: 4257.57
A17: 45012.61 | B17: 0.225 | C17: 7633.51
A18: 55976.17 | B18: 0.275 | C18: 10432.32
A20: Taxa Selic mensal (juros cobrados pela Receita) – conferir na fonte oficial (Banco Central, série 4390)
A21: Mês | B21: Selic no mês
A22: 43466 | B22: 0.0054
A23: 43497 | B23: 0.0049
A24: 43525 | B24: 0.0047
A25: 43556 | B25: 0.0052
A26: 43586 | B26: 0.0054
A27: 43617 | B27: 0.0047
A28: 43647 | B28: 0.0057
A29: 43678 | B29: 0.005
A30: 43709 | B30: 0.0046
A31: 43739 | B31: 0.0048
A32: 43770 | B32: 0.0038
A33: 43800 | B33: 0.0037
... A110: 46143 | B110: 0.0107
